2013.08.27 14:27:24 org.jivesoftware.openfire.nio.ConnectionHandler - ConnectionHandler reports unexpected exception for session: (SOCKET, R: /127.0.0.1:63239, L: /127.0.0.1:5222, S: 0.0.0.0/0.0.0.0:5222)
org.xml.sax.SAXParseException; lineNumber: 1; columnNumber: 1; El contenido no está permitido en el prólogo.
	at com.sun.org.apache.xerces.internal.parsers.AbstractSAXParser.parse(Unknown Source)
	at cl.clayster.exi.EXIProcessor.encode(EXIProcessor.java:67)
	at cl.clayster.exi.EXIEncoderFilter.messageSent(EXIEncoderFilter.java:28)
	at org.apache.mina.common.support.AbstractIoFilterChain.callNextMessageSent(AbstractIoFilterChain.java:320)
	at org.apache.mina.common.support.AbstractIoFilterChain.access$1200(AbstractIoFilterChain.java:53)
	at org.apache.mina.common.support.AbstractIoFilterChain$EntryImpl$1.messageSent(AbstractIoFilterChain.java:653)
	at org.apache.mina.common.support.AbstractIoFilterChain$HeadFilter.messageSent(AbstractIoFilterChain.java:504)
	at org.apache.mina.common.support.AbstractIoFilterChain.callNextMessageSent(AbstractIoFilterChain.java:320)
	at org.apache.mina.common.support.AbstractIoFilterChain.fireMessageSent(AbstractIoFilterChain.java:314)
	at org.apache.mina.transport.socket.nio.SocketIoProcessor.doFlush(SocketIoProcessor.java:408)
	at org.apache.mina.transport.socket.nio.SocketIoProcessor.doFlush(SocketIoProcessor.java:332)
	at org.apache.mina.transport.socket.nio.SocketIoProcessor.access$500(SocketIoProcessor.java:45)
	at org.apache.mina.transport.socket.nio.SocketIoProcessor$Worker.run(SocketIoProcessor.java:488)
	at org.apache.mina.util.NamePreservingRunnable.run(NamePreservingRunnable.java:51)
	at java.util.concurrent.ThreadPoolExecutor.runWorker(Unknown Source)
	at java.util.concurrent.ThreadPoolExecutor$Worker.run(Unknown Source)
	at java.lang.Thread.run(Unknown Source)
2013.08.27 14:27:24 org.jivesoftware.openfire.nio.ConnectionHandler - ConnectionHandler reports unexpected exception for session: (SOCKET, R: /127.0.0.1:63239, L: /127.0.0.1:5222, S: 0.0.0.0/0.0.0.0:5222)
org.xml.sax.SAXParseException; lineNumber: 1; columnNumber: 1; El contenido no está permitido en el prólogo.
	at com.sun.org.apache.xerces.internal.parsers.AbstractSAXParser.parse(Unknown Source)
	at cl.clayster.exi.EXIProcessor.encode(EXIProcessor.java:67)
	at cl.clayster.exi.EXIEncoderFilter.messageSent(EXIEncoderFilter.java:28)
	at org.apache.mina.common.support.AbstractIoFilterChain.callNextMessageSent(AbstractIoFilterChain.java:320)
	at org.apache.mina.common.support.AbstractIoFilterChain.access$1200(AbstractIoFilterChain.java:53)
	at org.apache.mina.common.support.AbstractIoFilterChain$EntryImpl$1.messageSent(AbstractIoFilterChain.java:653)
	at org.apache.mina.common.support.AbstractIoFilterChain$HeadFilter.messageSent(AbstractIoFilterChain.java:504)
	at org.apache.mina.common.support.AbstractIoFilterChain.callNextMessageSent(AbstractIoFilterChain.java:320)
	at org.apache.mina.common.support.AbstractIoFilterChain.fireMessageSent(AbstractIoFilterChain.java:314)
	at org.apache.mina.transport.socket.nio.SocketIoProcessor.doFlush(SocketIoProcessor.java:408)
	at org.apache.mina.transport.socket.nio.SocketIoProcessor.doFlush(SocketIoProcessor.java:332)
	at org.apache.mina.transport.socket.nio.SocketIoProcessor.access$500(SocketIoProcessor.java:45)
	at org.apache.mina.transport.socket.nio.SocketIoProcessor$Worker.run(SocketIoProcessor.java:488)
	at org.apache.mina.util.NamePreservingRunnable.run(NamePreservingRunnable.java:51)
	at java.util.concurrent.ThreadPoolExecutor.runWorker(Unknown Source)
	at java.util.concurrent.ThreadPoolExecutor$Worker.run(Unknown Source)
	at java.lang.Thread.run(Unknown Source)
2013.08.27 14:27:25 org.jivesoftware.openfire.nio.ConnectionHandler - ConnectionHandler reports unexpected exception for session: (SOCKET, R: /127.0.0.1:63239, L: /127.0.0.1:5222, S: 0.0.0.0/0.0.0.0:5222)
org.xml.sax.SAXParseException; lineNumber: 1; columnNumber: 1; El contenido no está permitido en el prólogo.
	at com.sun.org.apache.xerces.internal.parsers.AbstractSAXParser.parse(Unknown Source)
	at cl.clayster.exi.EXIProcessor.encode(EXIProcessor.java:67)
	at cl.clayster.exi.EXIEncoderFilter.messageSent(EXIEncoderFilter.java:28)
	at org.apache.mina.common.support.AbstractIoFilterChain.callNextMessageSent(AbstractIoFilterChain.java:320)
	at org.apache.mina.common.support.AbstractIoFilterChain.access$1200(AbstractIoFilterChain.java:53)
	at org.apache.mina.common.support.AbstractIoFilterChain$EntryImpl$1.messageSent(AbstractIoFilterChain.java:653)
	at org.apache.mina.common.support.AbstractIoFilterChain$HeadFilter.messageSent(AbstractIoFilterChain.java:504)
	at org.apache.mina.common.support.AbstractIoFilterChain.callNextMessageSent(AbstractIoFilterChain.java:320)
	at org.apache.mina.common.support.AbstractIoFilterChain.fireMessageSent(AbstractIoFilterChain.java:314)
	at org.apache.mina.transport.socket.nio.SocketIoProcessor.doFlush(SocketIoProcessor.java:408)
	at org.apache.mina.transport.socket.nio.SocketIoProcessor.doFlush(SocketIoProcessor.java:332)
	at org.apache.mina.transport.socket.nio.SocketIoProcessor.access$500(SocketIoProcessor.java:45)
	at org.apache.mina.transport.socket.nio.SocketIoProcessor$Worker.run(SocketIoProcessor.java:488)
	at org.apache.mina.util.NamePreservingRunnable.run(NamePreservingRunnable.java:51)
	at java.util.concurrent.ThreadPoolExecutor.runWorker(Unknown Source)
	at java.util.concurrent.ThreadPoolExecutor$Worker.run(Unknown Source)
	at java.lang.Thread.run(Unknown Source)
2013.08.27 14:27:31 org.jivesoftware.openfire.nio.ConnectionHandler - ConnectionHandler reports unexpected exception for session: (SOCKET, R: /127.0.0.1:63239, L: /127.0.0.1:5222, S: 0.0.0.0/0.0.0.0:5222)
org.xml.sax.SAXParseException; lineNumber: 1; columnNumber: 1; El contenido no está permitido en el prólogo.
	at com.sun.org.apache.xerces.internal.parsers.AbstractSAXParser.parse(Unknown Source)
	at cl.clayster.exi.EXIProcessor.encode(EXIProcessor.java:67)
	at cl.clayster.exi.EXIEncoderFilter.messageSent(EXIEncoderFilter.java:28)
	at org.apache.mina.common.support.AbstractIoFilterChain.callNextMessageSent(AbstractIoFilterChain.java:320)
	at org.apache.mina.common.support.AbstractIoFilterChain.access$1200(AbstractIoFilterChain.java:53)
	at org.apache.mina.common.support.AbstractIoFilterChain$EntryImpl$1.messageSent(AbstractIoFilterChain.java:653)
	at org.apache.mina.common.support.AbstractIoFilterChain$HeadFilter.messageSent(AbstractIoFilterChain.java:504)
	at org.apache.mina.common.support.AbstractIoFilterChain.callNextMessageSent(AbstractIoFilterChain.java:320)
	at org.apache.mina.common.support.AbstractIoFilterChain.fireMessageSent(AbstractIoFilterChain.java:314)
	at org.apache.mina.transport.socket.nio.SocketIoProcessor.doFlush(SocketIoProcessor.java:408)
	at org.apache.mina.transport.socket.nio.SocketIoProcessor.doFlush(SocketIoProcessor.java:332)
	at org.apache.mina.transport.socket.nio.SocketIoProcessor.access$500(SocketIoProcessor.java:45)
	at org.apache.mina.transport.socket.nio.SocketIoProcessor$Worker.run(SocketIoProcessor.java:488)
	at org.apache.mina.util.NamePreservingRunnable.run(NamePreservingRunnable.java:51)
	at java.util.concurrent.ThreadPoolExecutor.runWorker(Unknown Source)
	at java.util.concurrent.ThreadPoolExecutor$Worker.run(Unknown Source)
	at java.lang.Thread.run(Unknown Source)
2013.08.27 14:27:59 org.jivesoftware.openfire.nio.ConnectionHandler - ConnectionHandler reports unexpected exception for session: (SOCKET, R: /127.0.0.1:63239, L: /127.0.0.1:5222, S: 0.0.0.0/0.0.0.0:5222)
org.xml.sax.SAXParseException; lineNumber: 1; columnNumber: 1; El contenido no está permitido en el prólogo.
	at com.sun.org.apache.xerces.internal.parsers.AbstractSAXParser.parse(Unknown Source)
	at cl.clayster.exi.EXIProcessor.encode(EXIProcessor.java:67)
	at cl.clayster.exi.EXIEncoderFilter.messageSent(EXIEncoderFilter.java:28)
	at org.apache.mina.common.support.AbstractIoFilterChain.callNextMessageSent(AbstractIoFilterChain.java:320)
	at org.apache.mina.common.support.AbstractIoFilterChain.access$1200(AbstractIoFilterChain.java:53)
	at org.apache.mina.common.support.AbstractIoFilterChain$EntryImpl$1.messageSent(AbstractIoFilterChain.java:653)
	at org.apache.mina.common.support.AbstractIoFilterChain$HeadFilter.messageSent(AbstractIoFilterChain.java:504)
	at org.apache.mina.common.support.AbstractIoFilterChain.callNextMessageSent(AbstractIoFilterChain.java:320)
	at org.apache.mina.common.support.AbstractIoFilterChain.fireMessageSent(AbstractIoFilterChain.java:314)
	at org.apache.mina.transport.socket.nio.SocketIoProcessor.doFlush(SocketIoProcessor.java:408)
	at org.apache.mina.transport.socket.nio.SocketIoProcessor.doFlush(SocketIoProcessor.java:332)
	at org.apache.mina.transport.socket.nio.SocketIoProcessor.access$500(SocketIoProcessor.java:45)
	at org.apache.mina.transport.socket.nio.SocketIoProcessor$Worker.run(SocketIoProcessor.java:488)
	at org.apache.mina.util.NamePreservingRunnable.run(NamePreservingRunnable.java:51)
	at java.util.concurrent.ThreadPoolExecutor.runWorker(Unknown Source)
	at java.util.concurrent.ThreadPoolExecutor$Worker.run(Unknown Source)
	at java.lang.Thread.run(Unknown Source)
2013.08.27 15:11:08 org.jivesoftware.openfire.nio.ConnectionHandler - ConnectionHandler reports unexpected exception for session: (SOCKET, R: /127.0.0.1:63537, L: /127.0.0.1:5222, S: 0.0.0.0/0.0.0.0:5222)
org.xml.sax.SAXParseException; lineNumber: 1; columnNumber: 1; El contenido no está permitido en el prólogo.
	at com.sun.org.apache.xerces.internal.parsers.AbstractSAXParser.parse(Unknown Source)
	at cl.clayster.exi.EXIProcessor.encode(EXIProcessor.java:67)
	at cl.clayster.exi.EXIEncoderFilter.messageSent(EXIEncoderFilter.java:28)
	at org.apache.mina.common.support.AbstractIoFilterChain.callNextMessageSent(AbstractIoFilterChain.java:320)
	at org.apache.mina.common.support.AbstractIoFilterChain.access$1200(AbstractIoFilterChain.java:53)
	at org.apache.mina.common.support.AbstractIoFilterChain$EntryImpl$1.messageSent(AbstractIoFilterChain.java:653)
	at org.apache.mina.common.support.AbstractIoFilterChain$HeadFilter.messageSent(AbstractIoFilterChain.java:504)
	at org.apache.mina.common.support.AbstractIoFilterChain.callNextMessageSent(AbstractIoFilterChain.java:320)
	at org.apache.mina.common.support.AbstractIoFilterChain.fireMessageSent(AbstractIoFilterChain.java:314)
	at org.apache.mina.transport.socket.nio.SocketIoProcessor.doFlush(SocketIoProcessor.java:408)
	at org.apache.mina.transport.socket.nio.SocketIoProcessor.doFlush(SocketIoProcessor.java:332)
	at org.apache.mina.transport.socket.nio.SocketIoProcessor.access$500(SocketIoProcessor.java:45)
	at org.apache.mina.transport.socket.nio.SocketIoProcessor$Worker.run(SocketIoProcessor.java:488)
	at org.apache.mina.util.NamePreservingRunnable.run(NamePreservingRunnable.java:51)
	at java.util.concurrent.ThreadPoolExecutor.runWorker(Unknown Source)
	at java.util.concurrent.ThreadPoolExecutor$Worker.run(Unknown Source)
	at java.lang.Thread.run(Unknown Source)
2013.08.27 15:11:11 org.jivesoftware.openfire.nio.ConnectionHandler - ConnectionHandler reports unexpected exception for session: (SOCKET, R: /127.0.0.1:63537, L: /127.0.0.1:5222, S: 0.0.0.0/0.0.0.0:5222)
org.xml.sax.SAXParseException; lineNumber: 1; columnNumber: 1; El contenido no está permitido en el prólogo.
	at com.sun.org.apache.xerces.internal.parsers.AbstractSAXParser.parse(Unknown Source)
	at cl.clayster.exi.EXIProcessor.encode(EXIProcessor.java:67)
	at cl.clayster.exi.EXIEncoderFilter.messageSent(EXIEncoderFilter.java:28)
	at org.apache.mina.common.support.AbstractIoFilterChain.callNextMessageSent(AbstractIoFilterChain.java:320)
	at org.apache.mina.common.support.AbstractIoFilterChain.access$1200(AbstractIoFilterChain.java:53)
	at org.apache.mina.common.support.AbstractIoFilterChain$EntryImpl$1.messageSent(AbstractIoFilterChain.java:653)
	at org.apache.mina.common.support.AbstractIoFilterChain$HeadFilter.messageSent(AbstractIoFilterChain.java:504)
	at org.apache.mina.common.support.AbstractIoFilterChain.callNextMessageSent(AbstractIoFilterChain.java:320)
	at org.apache.mina.common.support.AbstractIoFilterChain.fireMessageSent(AbstractIoFilterChain.java:314)
	at org.apache.mina.transport.socket.nio.SocketIoProcessor.doFlush(SocketIoProcessor.java:408)
	at org.apache.mina.transport.socket.nio.SocketIoProcessor.doFlush(SocketIoProcessor.java:332)
	at org.apache.mina.transport.socket.nio.SocketIoProcessor.access$500(SocketIoProcessor.java:45)
	at org.apache.mina.transport.socket.nio.SocketIoProcessor$Worker.run(SocketIoProcessor.java:488)
	at org.apache.mina.util.NamePreservingRunnable.run(NamePreservingRunnable.java:51)
	at java.util.concurrent.ThreadPoolExecutor.runWorker(Unknown Source)
	at java.util.concurrent.ThreadPoolExecutor$Worker.run(Unknown Source)
	at java.lang.Thread.run(Unknown Source)
2013.08.27 15:11:12 org.jivesoftware.openfire.nio.ConnectionHandler - ConnectionHandler reports unexpected exception for session: (SOCKET, R: /127.0.0.1:63537, L: /127.0.0.1:5222, S: 0.0.0.0/0.0.0.0:5222)
org.xml.sax.SAXParseException; lineNumber: 1; columnNumber: 1; El contenido no está permitido en el prólogo.
	at com.sun.org.apache.xerces.internal.parsers.AbstractSAXParser.parse(Unknown Source)
	at cl.clayster.exi.EXIProcessor.encode(EXIProcessor.java:67)
	at cl.clayster.exi.EXIEncoderFilter.messageSent(EXIEncoderFilter.java:28)
	at org.apache.mina.common.support.AbstractIoFilterChain.callNextMessageSent(AbstractIoFilterChain.java:320)
	at org.apache.mina.common.support.AbstractIoFilterChain.access$1200(AbstractIoFilterChain.java:53)
	at org.apache.mina.common.support.AbstractIoFilterChain$EntryImpl$1.messageSent(AbstractIoFilterChain.java:653)
	at org.apache.mina.common.support.AbstractIoFilterChain$HeadFilter.messageSent(AbstractIoFilterChain.java:504)
	at org.apache.mina.common.support.AbstractIoFilterChain.callNextMessageSent(AbstractIoFilterChain.java:320)
	at org.apache.mina.common.support.AbstractIoFilterChain.fireMessageSent(AbstractIoFilterChain.java:314)
	at org.apache.mina.transport.socket.nio.SocketIoProcessor.doFlush(SocketIoProcessor.java:408)
	at org.apache.mina.transport.socket.nio.SocketIoProcessor.doFlush(SocketIoProcessor.java:332)
	at org.apache.mina.transport.socket.nio.SocketIoProcessor.access$500(SocketIoProcessor.java:45)
	at org.apache.mina.transport.socket.nio.SocketIoProcessor$Worker.run(SocketIoProcessor.java:488)
	at org.apache.mina.util.NamePreservingRunnable.run(NamePreservingRunnable.java:51)
	at java.util.concurrent.ThreadPoolExecutor.runWorker(Unknown Source)
	at java.util.concurrent.ThreadPoolExecutor$Worker.run(Unknown Source)
	at java.lang.Thread.run(Unknown Source)
2013.08.27 15:38:26 org.jivesoftware.openfire.nio.ConnectionHandler - ConnectionHandler reports unexpected exception for session: (SOCKET, R: /127.0.0.1:63728, L: /127.0.0.1:5222, S: 0.0.0.0/0.0.0.0:5222)
org.xml.sax.SAXParseException; lineNumber: 1; columnNumber: 1; El contenido no está permitido en el prólogo.
	at com.sun.org.apache.xerces.internal.parsers.AbstractSAXParser.parse(Unknown Source)
	at cl.clayster.exi.EXIProcessor.encode(EXIProcessor.java:67)
	at cl.clayster.exi.EXIEncoderFilter.messageSent(EXIEncoderFilter.java:28)
	at org.apache.mina.common.support.AbstractIoFilterChain.callNextMessageSent(AbstractIoFilterChain.java:320)
	at org.apache.mina.common.support.AbstractIoFilterChain.access$1200(AbstractIoFilterChain.java:53)
	at org.apache.mina.common.support.AbstractIoFilterChain$EntryImpl$1.messageSent(AbstractIoFilterChain.java:653)
	at org.apache.mina.common.support.AbstractIoFilterChain$HeadFilter.messageSent(AbstractIoFilterChain.java:504)
	at org.apache.mina.common.support.AbstractIoFilterChain.callNextMessageSent(AbstractIoFilterChain.java:320)
	at org.apache.mina.common.support.AbstractIoFilterChain.fireMessageSent(AbstractIoFilterChain.java:314)
	at org.apache.mina.transport.socket.nio.SocketIoProcessor.doFlush(SocketIoProcessor.java:408)
	at org.apache.mina.transport.socket.nio.SocketIoProcessor.doFlush(SocketIoProcessor.java:332)
	at org.apache.mina.transport.socket.nio.SocketIoProcessor.access$500(SocketIoProcessor.java:45)
	at org.apache.mina.transport.socket.nio.SocketIoProcessor$Worker.run(SocketIoProcessor.java:488)
	at org.apache.mina.util.NamePreservingRunnable.run(NamePreservingRunnable.java:51)
	at java.util.concurrent.ThreadPoolExecutor.runWorker(Unknown Source)
	at java.util.concurrent.ThreadPoolExecutor$Worker.run(Unknown Source)
	at java.lang.Thread.run(Unknown Source)
2013.08.27 15:38:51 org.jivesoftware.openfire.nio.ConnectionHandler - ConnectionHandler reports unexpected exception for session: (SOCKET, R: /127.0.0.1:63728, L: /127.0.0.1:5222, S: 0.0.0.0/0.0.0.0:5222)
org.xml.sax.SAXParseException; lineNumber: 1; columnNumber: 1; El contenido no está permitido en el prólogo.
	at com.sun.org.apache.xerces.internal.parsers.AbstractSAXParser.parse(Unknown Source)
	at cl.clayster.exi.EXIProcessor.encode(EXIProcessor.java:67)
	at cl.clayster.exi.EXIEncoderFilter.messageSent(EXIEncoderFilter.java:28)
	at org.apache.mina.common.support.AbstractIoFilterChain.callNextMessageSent(AbstractIoFilterChain.java:320)
	at org.apache.mina.common.support.AbstractIoFilterChain.access$1200(AbstractIoFilterChain.java:53)
	at org.apache.mina.common.support.AbstractIoFilterChain$EntryImpl$1.messageSent(AbstractIoFilterChain.java:653)
	at org.apache.mina.common.support.AbstractIoFilterChain$HeadFilter.messageSent(AbstractIoFilterChain.java:504)
	at org.apache.mina.common.support.AbstractIoFilterChain.callNextMessageSent(AbstractIoFilterChain.java:320)
	at org.apache.mina.common.support.AbstractIoFilterChain.fireMessageSent(AbstractIoFilterChain.java:314)
	at org.apache.mina.transport.socket.nio.SocketIoProcessor.doFlush(SocketIoProcessor.java:408)
	at org.apache.mina.transport.socket.nio.SocketIoProcessor.doFlush(SocketIoProcessor.java:332)
	at org.apache.mina.transport.socket.nio.SocketIoProcessor.access$500(SocketIoProcessor.java:45)
	at org.apache.mina.transport.socket.nio.SocketIoProcessor$Worker.run(SocketIoProcessor.java:488)
	at org.apache.mina.util.NamePreservingRunnable.run(NamePreservingRunnable.java:51)
	at java.util.concurrent.ThreadPoolExecutor.runWorker(Unknown Source)
	at java.util.concurrent.ThreadPoolExecutor$Worker.run(Unknown Source)
	at java.lang.Thread.run(Unknown Source)
2013.08.27 15:41:40 org.jivesoftware.openfire.nio.ConnectionHandler - ConnectionHandler reports unexpected exception for session: (SOCKET, R: /127.0.0.1:63822, L: /127.0.0.1:5222, S: 0.0.0.0/0.0.0.0:5222)
org.xml.sax.SAXParseException; lineNumber: 1; columnNumber: 1; El contenido no está permitido en el prólogo.
	at com.sun.org.apache.xerces.internal.parsers.AbstractSAXParser.parse(Unknown Source)
	at cl.clayster.exi.EXIProcessor.encode(EXIProcessor.java:67)
	at cl.clayster.exi.EXIEncoderFilter.messageSent(EXIEncoderFilter.java:28)
	at org.apache.mina.common.support.AbstractIoFilterChain.callNextMessageSent(AbstractIoFilterChain.java:320)
	at org.apache.mina.common.support.AbstractIoFilterChain.access$1200(AbstractIoFilterChain.java:53)
	at org.apache.mina.common.support.AbstractIoFilterChain$EntryImpl$1.messageSent(AbstractIoFilterChain.java:653)
	at org.apache.mina.common.support.AbstractIoFilterChain$HeadFilter.messageSent(AbstractIoFilterChain.java:504)
	at org.apache.mina.common.support.AbstractIoFilterChain.callNextMessageSent(AbstractIoFilterChain.java:320)
	at org.apache.mina.common.support.AbstractIoFilterChain.fireMessageSent(AbstractIoFilterChain.java:314)
	at org.apache.mina.transport.socket.nio.SocketIoProcessor.doFlush(SocketIoProcessor.java:408)
	at org.apache.mina.transport.socket.nio.SocketIoProcessor.doFlush(SocketIoProcessor.java:332)
	at org.apache.mina.transport.socket.nio.SocketIoProcessor.access$500(SocketIoProcessor.java:45)
	at org.apache.mina.transport.socket.nio.SocketIoProcessor$Worker.run(SocketIoProcessor.java:488)
	at org.apache.mina.util.NamePreservingRunnable.run(NamePreservingRunnable.java:51)
	at java.util.concurrent.ThreadPoolExecutor.runWorker(Unknown Source)
	at java.util.concurrent.ThreadPoolExecutor$Worker.run(Unknown Source)
	at java.lang.Thread.run(Unknown Source)
2013.08.27 16:15:56 org.jivesoftware.openfire.nio.ConnectionHandler - Closing connection due to error while processing message: ???6²¹¹°³²? H?ÛXXÚÝ\Ù\??]?Y\??XÙ[?Ú[ËÔÛXXÚä? ???3Ó??2ÔÂìÒÊä?ÔÂìÒÊä\àØÂÆÊÜÆÒß?A?Ú]# ¬Mì?0!½±??;£C?+$g9QpP0 
org.xmlpull.v1.XmlPullParserException: only whitespace content allowed before start tag and not \u80 (position: START_DOCUMENT seen \u80... @1:1) 
	at org.xmlpull.mxp1.MXParser.parseProlog(MXParser.java:1519)
	at org.jivesoftware.openfire.net.MXParser.nextImpl(MXParser.java:341)
	at org.xmlpull.mxp1.MXParser.nextToken(MXParser.java:1100)
	at org.dom4j.io.XMPPPacketReader.parseDocument(XMPPPacketReader.java:317)
	at org.dom4j.io.XMPPPacketReader.read(XMPPPacketReader.java:154)
	at org.jivesoftware.openfire.net.StanzaHandler.process(StanzaHandler.java:159)
	at org.jivesoftware.openfire.nio.ConnectionHandler.messageReceived(ConnectionHandler.java:189)
	at org.apache.mina.common.support.AbstractIoFilterChain$TailFilter.messageReceived(AbstractIoFilterChain.java:570)
	at org.apache.mina.common.support.AbstractIoFilterChain.callNextMessageReceived(AbstractIoFilterChain.java:299)
	at org.apache.mina.common.support.AbstractIoFilterChain.access$1100(AbstractIoFilterChain.java:53)
	at org.apache.mina.common.support.AbstractIoFilterChain$EntryImpl$1.messageReceived(AbstractIoFilterChain.java:648)
	at org.apache.mina.common.IoFilterAdapter.messageReceived(IoFilterAdapter.java:80)
	at org.apache.mina.common.support.AbstractIoFilterChain.callNextMessageReceived(AbstractIoFilterChain.java:299)
	at org.apache.mina.common.support.AbstractIoFilterChain.access$1100(AbstractIoFilterChain.java:53)
	at org.apache.mina.common.support.AbstractIoFilterChain$EntryImpl$1.messageReceived(AbstractIoFilterChain.java:648)
	at org.apache.mina.filter.codec.support.SimpleProtocolDecoderOutput.flush(SimpleProtocolDecoderOutput.java:58)
	at org.apache.mina.filter.codec.ProtocolCodecFilter.messageReceived(ProtocolCodecFilter.java:185)
	at org.apache.mina.common.support.AbstractIoFilterChain.callNextMessageReceived(AbstractIoFilterChain.java:299)
	at org.apache.mina.common.support.AbstractIoFilterChain.access$1100(AbstractIoFilterChain.java:53)
	at org.apache.mina.common.support.AbstractIoFilterChain$EntryImpl$1.messageReceived(AbstractIoFilterChain.java:648)
	at org.apache.mina.common.IoFilterAdapter.messageReceived(IoFilterAdapter.java:80)
	at org.jivesoftware.openfire.plugin.RawPrintFilter.messageReceived(RawPrintFilter.java:66)
	at org.apache.mina.common.support.AbstractIoFilterChain.callNextMessageReceived(AbstractIoFilterChain.java:299)
	at org.apache.mina.common.support.AbstractIoFilterChain.access$1100(AbstractIoFilterChain.java:53)
	at org.apache.mina.common.support.AbstractIoFilterChain$EntryImpl$1.messageReceived(AbstractIoFilterChain.java:648)
	at org.apache.mina.common.IoFilterAdapter.messageReceived(IoFilterAdapter.java:80)
	at cl.clayster.exi.EXIDecoderFilter.messageReceived(EXIDecoderFilter.java:38)
	at org.apache.mina.common.support.AbstractIoFilterChain.callNextMessageReceived(AbstractIoFilterChain.java:299)
	at org.apache.mina.common.support.AbstractIoFilterChain.access$1100(AbstractIoFilterChain.java:53)
	at org.apache.mina.common.support.AbstractIoFilterChain$EntryImpl$1.messageReceived(AbstractIoFilterChain.java:648)
	at org.apache.mina.common.IoFilterAdapter.messageReceived(IoFilterAdapter.java:80)
	at cl.clayster.exi.EXIFilter.messageReceived(EXIFilter.java:56)
	at org.apache.mina.common.support.AbstractIoFilterChain.callNextMessageReceived(AbstractIoFilterChain.java:299)
	at org.apache.mina.common.support.AbstractIoFilterChain.access$1100(AbstractIoFilterChain.java:53)
	at org.apache.mina.common.support.AbstractIoFilterChain$EntryImpl$1.messageReceived(AbstractIoFilterChain.java:648)
	at org.apache.mina.filter.executor.ExecutorFilter.processEvent(ExecutorFilter.java:239)
	at org.apache.mina.filter.executor.ExecutorFilter$ProcessEventsRunnable.run(ExecutorFilter.java:283)
	at java.util.concurrent.ThreadPoolExecutor.runWorker(Unknown Source)
	at java.util.concurrent.ThreadPoolExecutor$Worker.run(Unknown Source)
	at org.apache.mina.util.NamePreservingRunnable.run(NamePreservingRunnable.java:51)
	at java.lang.Thread.run(Unknown Source)
2013.08.27 17:06:14 org.jivesoftware.openfire.nio.ConnectionHandler - ConnectionHandler reports unexpected exception for session: (SOCKET, R: /127.0.0.1:65077, L: /127.0.0.1:5222, S: 0.0.0.0/0.0.0.0:5222)
org.xml.sax.SAXParseException; lineNumber: 1; columnNumber: 1; El contenido no está permitido en el prólogo.
	at com.sun.org.apache.xerces.internal.parsers.AbstractSAXParser.parse(Unknown Source)
	at cl.clayster.exi.EXIProcessor.encodeByteBuffer(EXIProcessor.java:67)
	at cl.clayster.exi.EXIEncoderFilter.messageSent(EXIEncoderFilter.java:24)
	at org.apache.mina.common.support.AbstractIoFilterChain.callNextMessageSent(AbstractIoFilterChain.java:320)
	at org.apache.mina.common.support.AbstractIoFilterChain.access$1200(AbstractIoFilterChain.java:53)
	at org.apache.mina.common.support.AbstractIoFilterChain$EntryImpl$1.messageSent(AbstractIoFilterChain.java:653)
	at org.apache.mina.common.support.AbstractIoFilterChain$HeadFilter.messageSent(AbstractIoFilterChain.java:504)
	at org.apache.mina.common.support.AbstractIoFilterChain.callNextMessageSent(AbstractIoFilterChain.java:320)
	at org.apache.mina.common.support.AbstractIoFilterChain.fireMessageSent(AbstractIoFilterChain.java:314)
	at org.apache.mina.transport.socket.nio.SocketIoProcessor.doFlush(SocketIoProcessor.java:408)
	at org.apache.mina.transport.socket.nio.SocketIoProcessor.doFlush(SocketIoProcessor.java:332)
	at org.apache.mina.transport.socket.nio.SocketIoProcessor.access$500(SocketIoProcessor.java:45)
	at org.apache.mina.transport.socket.nio.SocketIoProcessor$Worker.run(SocketIoProcessor.java:488)
	at org.apache.mina.util.NamePreservingRunnable.run(NamePreservingRunnable.java:51)
	at java.util.concurrent.ThreadPoolExecutor.runWorker(Unknown Source)
	at java.util.concurrent.ThreadPoolExecutor$Worker.run(Unknown Source)
	at java.lang.Thread.run(Unknown Source)
2013.08.27 17:06:14 org.jivesoftware.openfire.nio.ConnectionHandler - ConnectionHandler reports unexpected exception for session: (SOCKET, R: /127.0.0.1:65077, L: /127.0.0.1:5222, S: 0.0.0.0/0.0.0.0:5222)
org.xml.sax.SAXParseException; lineNumber: 1; columnNumber: 1; El contenido no está permitido en el prólogo.
	at com.sun.org.apache.xerces.internal.parsers.AbstractSAXParser.parse(Unknown Source)
	at cl.clayster.exi.EXIProcessor.encodeByteBuffer(EXIProcessor.java:67)
	at cl.clayster.exi.EXIEncoderFilter.messageSent(EXIEncoderFilter.java:24)
	at org.apache.mina.common.support.AbstractIoFilterChain.callNextMessageSent(AbstractIoFilterChain.java:320)
	at org.apache.mina.common.support.AbstractIoFilterChain.access$1200(AbstractIoFilterChain.java:53)
	at org.apache.mina.common.support.AbstractIoFilterChain$EntryImpl$1.messageSent(AbstractIoFilterChain.java:653)
	at org.apache.mina.common.support.AbstractIoFilterChain$HeadFilter.messageSent(AbstractIoFilterChain.java:504)
	at org.apache.mina.common.support.AbstractIoFilterChain.callNextMessageSent(AbstractIoFilterChain.java:320)
	at org.apache.mina.common.support.AbstractIoFilterChain.fireMessageSent(AbstractIoFilterChain.java:314)
	at org.apache.mina.transport.socket.nio.SocketIoProcessor.doFlush(SocketIoProcessor.java:408)
	at org.apache.mina.transport.socket.nio.SocketIoProcessor.doFlush(SocketIoProcessor.java:332)
	at org.apache.mina.transport.socket.nio.SocketIoProcessor.access$500(SocketIoProcessor.java:45)
	at org.apache.mina.transport.socket.nio.SocketIoProcessor$Worker.run(SocketIoProcessor.java:488)
	at org.apache.mina.util.NamePreservingRunnable.run(NamePreservingRunnable.java:51)
	at java.util.concurrent.ThreadPoolExecutor.runWorker(Unknown Source)
	at java.util.concurrent.ThreadPoolExecutor$Worker.run(Unknown Source)
	at java.lang.Thread.run(Unknown Source)
2013.08.27 17:07:29 org.jivesoftware.openfire.nio.ConnectionHandler - ConnectionHandler reports unexpected exception for session: (SOCKET, R: /127.0.0.1:65077, L: /127.0.0.1:5222, S: 0.0.0.0/0.0.0.0:5222)
org.xml.sax.SAXParseException; lineNumber: 1; columnNumber: 1; El contenido no está permitido en el prólogo.
	at com.sun.org.apache.xerces.internal.parsers.AbstractSAXParser.parse(Unknown Source)
	at cl.clayster.exi.EXIProcessor.encodeByteBuffer(EXIProcessor.java:67)
	at cl.clayster.exi.EXIEncoderFilter.messageSent(EXIEncoderFilter.java:24)
	at org.apache.mina.common.support.AbstractIoFilterChain.callNextMessageSent(AbstractIoFilterChain.java:320)
	at org.apache.mina.common.support.AbstractIoFilterChain.access$1200(AbstractIoFilterChain.java:53)
	at org.apache.mina.common.support.AbstractIoFilterChain$EntryImpl$1.messageSent(AbstractIoFilterChain.java:653)
	at org.apache.mina.common.support.AbstractIoFilterChain$HeadFilter.messageSent(AbstractIoFilterChain.java:504)
	at org.apache.mina.common.support.AbstractIoFilterChain.callNextMessageSent(AbstractIoFilterChain.java:320)
	at org.apache.mina.common.support.AbstractIoFilterChain.fireMessageSent(AbstractIoFilterChain.java:314)
	at org.apache.mina.transport.socket.nio.SocketIoProcessor.doFlush(SocketIoProcessor.java:408)
	at org.apache.mina.transport.socket.nio.SocketIoProcessor.doFlush(SocketIoProcessor.java:332)
	at org.apache.mina.transport.socket.nio.SocketIoProcessor.access$500(SocketIoProcessor.java:45)
	at org.apache.mina.transport.socket.nio.SocketIoProcessor$Worker.run(SocketIoProcessor.java:488)
	at org.apache.mina.util.NamePreservingRunnable.run(NamePreservingRunnable.java:51)
	at java.util.concurrent.ThreadPoolExecutor.runWorker(Unknown Source)
	at java.util.concurrent.ThreadPoolExecutor$Worker.run(Unknown Source)
	at java.lang.Thread.run(Unknown Source)
2013.08.27 17:08:22 org.jivesoftware.openfire.nio.ConnectionHandler - ConnectionHandler reports unexpected exception for session: (SOCKET, R: /127.0.0.1:65077, L: /127.0.0.1:5222, S: 0.0.0.0/0.0.0.0:5222)
org.xml.sax.SAXParseException; lineNumber: 1; columnNumber: 1; El contenido no está permitido en el prólogo.
	at com.sun.org.apache.xerces.internal.parsers.AbstractSAXParser.parse(Unknown Source)
	at cl.clayster.exi.EXIProcessor.encodeByteBuffer(EXIProcessor.java:67)
	at cl.clayster.exi.EXIEncoderFilter.messageSent(EXIEncoderFilter.java:24)
	at org.apache.mina.common.support.AbstractIoFilterChain.callNextMessageSent(AbstractIoFilterChain.java:320)
	at org.apache.mina.common.support.AbstractIoFilterChain.access$1200(AbstractIoFilterChain.java:53)
	at org.apache.mina.common.support.AbstractIoFilterChain$EntryImpl$1.messageSent(AbstractIoFilterChain.java:653)
	at org.apache.mina.common.support.AbstractIoFilterChain$HeadFilter.messageSent(AbstractIoFilterChain.java:504)
	at org.apache.mina.common.support.AbstractIoFilterChain.callNextMessageSent(AbstractIoFilterChain.java:320)
	at org.apache.mina.common.support.AbstractIoFilterChain.fireMessageSent(AbstractIoFilterChain.java:314)
	at org.apache.mina.transport.socket.nio.SocketIoProcessor.doFlush(SocketIoProcessor.java:408)
	at org.apache.mina.transport.socket.nio.SocketIoProcessor.doFlush(SocketIoProcessor.java:332)
	at org.apache.mina.transport.socket.nio.SocketIoProcessor.access$500(SocketIoProcessor.java:45)
	at org.apache.mina.transport.socket.nio.SocketIoProcessor$Worker.run(SocketIoProcessor.java:488)
	at org.apache.mina.util.NamePreservingRunnable.run(NamePreservingRunnable.java:51)
	at java.util.concurrent.ThreadPoolExecutor.runWorker(Unknown Source)
	at java.util.concurrent.ThreadPoolExecutor$Worker.run(Unknown Source)
	at java.lang.Thread.run(Unknown Source)
2013.09.10 13:06:02 org.jivesoftware.database.DbConnectionManager - The database is already in use by another process: org.hsqldb.persist.NIOLockFile@8aa1e602[file =C:\Users\Javier\workspace\Personales\openfire\target\openfire\embedded-db\openfire.lck, exists=true, locked=false, valid=false, fl =null]: java.lang.Exception: checkHeartbeat(): lock file [C:\Users\Javier\workspace\Personales\openfire\target\openfire\embedded-db\openfire.lck] is presumably locked by another process.
java.sql.SQLException: The database is already in use by another process: org.hsqldb.persist.NIOLockFile@8aa1e602[file =C:\Users\Javier\workspace\Personales\openfire\target\openfire\embedded-db\openfire.lck, exists=true, locked=false, valid=false, fl =null]: java.lang.Exception: checkHeartbeat(): lock file [C:\Users\Javier\workspace\Personales\openfire\target\openfire\embedded-db\openfire.lck] is presumably locked by another process.
	at org.hsqldb.jdbc.Util.sqlException(Unknown Source)
	at org.hsqldb.jdbc.jdbcConnection.<init>(Unknown Source)
	at org.hsqldb.jdbcDriver.getConnection(Unknown Source)
	at org.hsqldb.jdbcDriver.connect(Unknown Source)
	at java.sql.DriverManager.getConnection(Unknown Source)
	at java.sql.DriverManager.getConnection(Unknown Source)
	at org.logicalcobwebs.proxool.DefaultConnectionBuilder.buildConnection(DefaultConnectionBuilder.java:39)
	at org.logicalcobwebs.proxool.Prototyper.buildConnection(Prototyper.java:159)
	at org.logicalcobwebs.proxool.ConnectionPool.getConnection(ConnectionPool.java:211)
	at org.logicalcobwebs.proxool.ProxoolDriver.connect(ProxoolDriver.java:89)
	at java.sql.DriverManager.getConnection(Unknown Source)
	at java.sql.DriverManager.getConnection(Unknown Source)
	at org.jivesoftware.database.EmbeddedConnectionProvider.getConnection(EmbeddedConnectionProvider.java:61)
	at org.jivesoftware.database.DbConnectionManager.setConnectionProvider(DbConnectionManager.java:620)
	at org.jivesoftware.database.DbConnectionManager.getConnection(DbConnectionManager.java:100)
	at org.jivesoftware.util.JiveProperties.loadProperties(JiveProperties.java:344)
	at org.jivesoftware.util.JiveProperties.init(JiveProperties.java:90)
	at org.jivesoftware.util.JiveProperties$JivePropertyHolder.<clinit>(JiveProperties.java:57)
	at org.jivesoftware.util.JiveProperties.getInstance(JiveProperties.java:69)
	at org.jivesoftware.util.JiveGlobals.getProperty(JiveGlobals.java:551)
	at org.jivesoftware.openfire.XMPPServer.initialize(XMPPServer.java:353)
	at org.jivesoftware.openfire.XMPPServer.start(XMPPServer.java:474)
	at org.jivesoftware.openfire.XMPPServer.<init>(XMPPServer.java:216)
	at sun.reflect.NativeConstructorAccessorImpl.newInstance0(Native Method)
	at sun.reflect.NativeConstructorAccessorImpl.newInstance(Unknown Source)
	at sun.reflect.DelegatingConstructorAccessorImpl.newInstance(Unknown Source)
	at java.lang.reflect.Constructor.newInstance(Unknown Source)
	at java.lang.Class.newInstance0(Unknown Source)
	at java.lang.Class.newInstance(Unknown Source)
	at org.jivesoftware.openfire.starter.ServerStarter.start(ServerStarter.java:113)
	at org.jivesoftware.openfire.starter.ServerStarter.main(ServerStarter.java:58)
2013.09.10 13:06:02 org.jivesoftware.util.log.util.CommonsLogFactory - Prototype
java.sql.SQLException: The database is already in use by another process: org.hsqldb.persist.NIOLockFile@8aa1e602[file =C:\Users\Javier\workspace\Personales\openfire\target\openfire\embedded-db\openfire.lck, exists=true, locked=false, valid=false, fl =null]: java.lang.Exception: checkHeartbeat(): lock file [C:\Users\Javier\workspace\Personales\openfire\target\openfire\embedded-db\openfire.lck] is presumably locked by another process.
	at org.hsqldb.jdbc.Util.sqlException(Unknown Source)
	at org.hsqldb.jdbc.jdbcConnection.<init>(Unknown Source)
	at org.hsqldb.jdbcDriver.getConnection(Unknown Source)
	at org.hsqldb.jdbcDriver.connect(Unknown Source)
	at java.sql.DriverManager.getConnection(Unknown Source)
	at java.sql.DriverManager.getConnection(Unknown Source)
	at org.logicalcobwebs.proxool.DefaultConnectionBuilder.buildConnection(DefaultConnectionBuilder.java:39)
	at org.logicalcobwebs.proxool.Prototyper.buildConnection(Prototyper.java:159)
	at org.logicalcobwebs.proxool.Prototyper.sweep(Prototyper.java:102)
	at org.logicalcobwebs.proxool.PrototyperThread.run(PrototyperThread.java:44)
2013.09.17 10:38:04 org.jivesoftware.openfire.container.PluginManager - Error loading plugin: C:\Users\Javier\workspace\Personales\openfire\target\openfire\plugins\exi
java.lang.NullPointerException: Parameter interceptor was null.
	at org.jivesoftware.openfire.interceptor.InterceptorManager.addInterceptor(InterceptorManager.java:90)
	at cl.clayster.exi.EXIPlugin.initializePlugin(EXIPlugin.java:29)
	at org.jivesoftware.openfire.container.PluginManager.loadPlugin(PluginManager.java:483)
	at org.jivesoftware.openfire.container.PluginManager.access$1(PluginManager.java:282)
	at org.jivesoftware.openfire.container.PluginManager$PluginMonitor.run(PluginManager.java:1073)
	at java.util.concurrent.Executors$RunnableAdapter.call(Unknown Source)
	at java.util.concurrent.FutureTask$Sync.innerRunAndReset(Unknown Source)
	at java.util.concurrent.FutureTask.runAndReset(Unknown Source)
	at java.util.concurrent.ScheduledThreadPoolExecutor$ScheduledFutureTask.access$301(Unknown Source)
	at java.util.concurrent.ScheduledThreadPoolExecutor$ScheduledFutureTask.run(Unknown Source)
	at java.util.concurrent.ThreadPoolExecutor.runWorker(Unknown Source)
	at java.util.concurrent.ThreadPoolExecutor$Worker.run(Unknown Source)
	at java.lang.Thread.run(Unknown Source)
2013.09.17 10:39:14 org.jivesoftware.openfire.container.PluginManager - Error loading plugin: C:\Users\Javier\workspace\Personales\openfire\target\openfire\plugins\exi
java.lang.NullPointerException: Parameter interceptor was null.
	at org.jivesoftware.openfire.interceptor.InterceptorManager.addInterceptor(InterceptorManager.java:90)
	at cl.clayster.exi.EXIPlugin.initializePlugin(EXIPlugin.java:29)
	at org.jivesoftware.openfire.container.PluginManager.loadPlugin(PluginManager.java:483)
	at org.jivesoftware.openfire.container.PluginManager.access$1(PluginManager.java:282)
	at org.jivesoftware.openfire.container.PluginManager$PluginMonitor.run(PluginManager.java:1073)
	at java.util.concurrent.Executors$RunnableAdapter.call(Unknown Source)
	at java.util.concurrent.FutureTask$Sync.innerRunAndReset(Unknown Source)
	at java.util.concurrent.FutureTask.runAndReset(Unknown Source)
	at java.util.concurrent.ScheduledThreadPoolExecutor$ScheduledFutureTask.access$301(Unknown Source)
	at java.util.concurrent.ScheduledThreadPoolExecutor$ScheduledFutureTask.run(Unknown Source)
	at java.util.concurrent.ThreadPoolExecutor.runWorker(Unknown Source)
	at java.util.concurrent.ThreadPoolExecutor$Worker.run(Unknown Source)
	at java.lang.Thread.run(Unknown Source)
2013.09.17 10:40:15 org.jivesoftware.openfire.container.PluginManager - Error loading plugin: C:\Users\Javier\workspace\Personales\openfire\target\openfire\plugins\exi
java.lang.NullPointerException: Parameter interceptor was null.
	at org.jivesoftware.openfire.interceptor.InterceptorManager.addInterceptor(InterceptorManager.java:90)
	at cl.clayster.exi.EXIPlugin.initializePlugin(EXIPlugin.java:29)
	at org.jivesoftware.openfire.container.PluginManager.loadPlugin(PluginManager.java:483)
	at org.jivesoftware.openfire.container.PluginManager.access$1(PluginManager.java:282)
	at org.jivesoftware.openfire.container.PluginManager$PluginMonitor.run(PluginManager.java:1073)
	at java.util.concurrent.Executors$RunnableAdapter.call(Unknown Source)
	at java.util.concurrent.FutureTask$Sync.innerRunAndReset(Unknown Source)
	at java.util.concurrent.FutureTask.runAndReset(Unknown Source)
	at java.util.concurrent.ScheduledThreadPoolExecutor$ScheduledFutureTask.access$301(Unknown Source)
	at java.util.concurrent.ScheduledThreadPoolExecutor$ScheduledFutureTask.run(Unknown Source)
	at java.util.concurrent.ThreadPoolExecutor.runWorker(Unknown Source)
	at java.util.concurrent.ThreadPoolExecutor$Worker.run(Unknown Source)
	at java.lang.Thread.run(Unknown Source)
2013.09.17 10:41:45 org.jivesoftware.openfire.container.PluginManager - Error loading plugin: C:\Users\Javier\workspace\Personales\openfire\target\openfire\plugins\exi
java.lang.NullPointerException: Parameter interceptor was null.
	at org.jivesoftware.openfire.interceptor.InterceptorManager.addInterceptor(InterceptorManager.java:90)
	at cl.clayster.exi.EXIPlugin.initializePlugin(EXIPlugin.java:29)
	at org.jivesoftware.openfire.container.PluginManager.loadPlugin(PluginManager.java:483)
	at org.jivesoftware.openfire.container.PluginManager.access$1(PluginManager.java:282)
	at org.jivesoftware.openfire.container.PluginManager$PluginMonitor.run(PluginManager.java:1073)
	at java.util.concurrent.Executors$RunnableAdapter.call(Unknown Source)
	at java.util.concurrent.FutureTask$Sync.innerRunAndReset(Unknown Source)
	at java.util.concurrent.FutureTask.runAndReset(Unknown Source)
	at java.util.concurrent.ScheduledThreadPoolExecutor$ScheduledFutureTask.access$301(Unknown Source)
	at java.util.concurrent.ScheduledThreadPoolExecutor$ScheduledFutureTask.run(Unknown Source)
	at java.util.concurrent.ThreadPoolExecutor.runWorker(Unknown Source)
	at java.util.concurrent.ThreadPoolExecutor$Worker.run(Unknown Source)
	at java.lang.Thread.run(Unknown Source)
2013.09.17 10:42:51 org.jivesoftware.openfire.container.PluginManager - Error loading plugin: C:\Users\Javier\workspace\Personales\openfire\target\openfire\plugins\exi
java.lang.NullPointerException: Parameter interceptor was null.
	at org.jivesoftware.openfire.interceptor.InterceptorManager.addInterceptor(InterceptorManager.java:90)
	at cl.clayster.exi.EXIPlugin.initializePlugin(EXIPlugin.java:29)
	at org.jivesoftware.openfire.container.PluginManager.loadPlugin(PluginManager.java:483)
	at org.jivesoftware.openfire.container.PluginManager.access$1(PluginManager.java:282)
	at org.jivesoftware.openfire.container.PluginManager$PluginMonitor.run(PluginManager.java:1073)
	at java.util.concurrent.Executors$RunnableAdapter.call(Unknown Source)
	at java.util.concurrent.FutureTask$Sync.innerRunAndReset(Unknown Source)
	at java.util.concurrent.FutureTask.runAndReset(Unknown Source)
	at java.util.concurrent.ScheduledThreadPoolExecutor$ScheduledFutureTask.access$301(Unknown Source)
	at java.util.concurrent.ScheduledThreadPoolExecutor$ScheduledFutureTask.run(Unknown Source)
	at java.util.concurrent.ThreadPoolExecutor.runWorker(Unknown Source)
	at java.util.concurrent.ThreadPoolExecutor$Worker.run(Unknown Source)
	at java.lang.Thread.run(Unknown Source)
2013.09.17 10:44:23 org.jivesoftware.openfire.container.PluginManager - Error loading plugin: C:\Users\Javier\workspace\Personales\openfire\target\openfire\plugins\exi
java.lang.NullPointerException: Parameter interceptor was null.
	at org.jivesoftware.openfire.interceptor.InterceptorManager.addInterceptor(InterceptorManager.java:90)
	at cl.clayster.exi.EXIPlugin.initializePlugin(EXIPlugin.java:29)
	at org.jivesoftware.openfire.container.PluginManager.loadPlugin(PluginManager.java:483)
	at org.jivesoftware.openfire.container.PluginManager.access$1(PluginManager.java:282)
	at org.jivesoftware.openfire.container.PluginManager$PluginMonitor.run(PluginManager.java:1073)
	at java.util.concurrent.Executors$RunnableAdapter.call(Unknown Source)
	at java.util.concurrent.FutureTask$Sync.innerRunAndReset(Unknown Source)
	at java.util.concurrent.FutureTask.runAndReset(Unknown Source)
	at java.util.concurrent.ScheduledThreadPoolExecutor$ScheduledFutureTask.access$301(Unknown Source)
	at java.util.concurrent.ScheduledThreadPoolExecutor$ScheduledFutureTask.run(Unknown Source)
	at java.util.concurrent.ThreadPoolExecutor.runWorker(Unknown Source)
	at java.util.concurrent.ThreadPoolExecutor$Worker.run(Unknown Source)
	at java.lang.Thread.run(Unknown Source)
2013.09.17 10:57:17 org.jivesoftware.util.log.util.CommonsLogFactory - Prototype
java.sql.SQLException: The database is already in use by another process: org.hsqldb.persist.NIOLockFile@8aa1e602[file =C:\Users\Javier\workspace\Personales\openfire\target\openfire\embedded-db\openfire.lck, exists=true, locked=false, valid=false, fl =null]: java.lang.Exception:  java.io.IOException: El proceso no tiene acceso al archivo porque otro proceso tiene bloqueada una parte del archivo : C:\Users\Javier\workspace\Personales\openfire\target\openfire\embedded-db\openfire.lck
	at org.hsqldb.jdbc.Util.sqlException(Unknown Source)
	at org.hsqldb.jdbc.jdbcConnection.<init>(Unknown Source)
	at org.hsqldb.jdbcDriver.getConnection(Unknown Source)
	at org.hsqldb.jdbcDriver.connect(Unknown Source)
	at java.sql.DriverManager.getConnection(Unknown Source)
	at java.sql.DriverManager.getConnection(Unknown Source)
	at org.logicalcobwebs.proxool.DefaultConnectionBuilder.buildConnection(DefaultConnectionBuilder.java:39)
	at org.logicalcobwebs.proxool.Prototyper.buildConnection(Prototyper.java:159)
	at org.logicalcobwebs.proxool.Prototyper.sweep(Prototyper.java:102)
	at org.logicalcobwebs.proxool.PrototyperThread.run(PrototyperThread.java:44)
2013.09.17 10:57:17 org.jivesoftware.database.DbConnectionManager - The database is already in use by another process: org.hsqldb.persist.NIOLockFile@8aa1e602[file =C:\Users\Javier\workspace\Personales\openfire\target\openfire\embedded-db\openfire.lck, exists=true, locked=false, valid=false, fl =null]: java.lang.Exception:  java.io.IOException: El proceso no tiene acceso al archivo porque otro proceso tiene bloqueada una parte del archivo : C:\Users\Javier\workspace\Personales\openfire\target\openfire\embedded-db\openfire.lck
java.sql.SQLException: The database is already in use by another process: org.hsqldb.persist.NIOLockFile@8aa1e602[file =C:\Users\Javier\workspace\Personales\openfire\target\openfire\embedded-db\openfire.lck, exists=true, locked=false, valid=false, fl =null]: java.lang.Exception:  java.io.IOException: El proceso no tiene acceso al archivo porque otro proceso tiene bloqueada una parte del archivo : C:\Users\Javier\workspace\Personales\openfire\target\openfire\embedded-db\openfire.lck
	at org.hsqldb.jdbc.Util.sqlException(Unknown Source)
	at org.hsqldb.jdbc.jdbcConnection.<init>(Unknown Source)
	at org.hsqldb.jdbcDriver.getConnection(Unknown Source)
	at org.hsqldb.jdbcDriver.connect(Unknown Source)
	at java.sql.DriverManager.getConnection(Unknown Source)
	at java.sql.DriverManager.getConnection(Unknown Source)
	at org.logicalcobwebs.proxool.DefaultConnectionBuilder.buildConnection(DefaultConnectionBuilder.java:39)
	at org.logicalcobwebs.proxool.Prototyper.buildConnection(Prototyper.java:159)
	at org.logicalcobwebs.proxool.ConnectionPool.getConnection(ConnectionPool.java:211)
	at org.logicalcobwebs.proxool.ProxoolDriver.connect(ProxoolDriver.java:89)
	at java.sql.DriverManager.getConnection(Unknown Source)
	at java.sql.DriverManager.getConnection(Unknown Source)
	at org.jivesoftware.database.EmbeddedConnectionProvider.getConnection(EmbeddedConnectionProvider.java:61)
	at org.jivesoftware.database.DbConnectionManager.setConnectionProvider(DbConnectionManager.java:620)
	at org.jivesoftware.database.DbConnectionManager.getConnection(DbConnectionManager.java:100)
	at org.jivesoftware.util.JiveProperties.loadProperties(JiveProperties.java:344)
	at org.jivesoftware.util.JiveProperties.init(JiveProperties.java:90)
	at org.jivesoftware.util.JiveProperties$JivePropertyHolder.<clinit>(JiveProperties.java:57)
	at org.jivesoftware.util.JiveProperties.getInstance(JiveProperties.java:69)
	at org.jivesoftware.util.JiveGlobals.getProperty(JiveGlobals.java:551)
	at org.jivesoftware.openfire.XMPPServer.initialize(XMPPServer.java:353)
	at org.jivesoftware.openfire.XMPPServer.start(XMPPServer.java:474)
	at org.jivesoftware.openfire.XMPPServer.<init>(XMPPServer.java:216)
	at sun.reflect.NativeConstructorAccessorImpl.newInstance0(Native Method)
	at sun.reflect.NativeConstructorAccessorImpl.newInstance(Unknown Source)
	at sun.reflect.DelegatingConstructorAccessorImpl.newInstance(Unknown Source)
	at java.lang.reflect.Constructor.newInstance(Unknown Source)
	at java.lang.Class.newInstance0(Unknown Source)
	at java.lang.Class.newInstance(Unknown Source)
	at org.jivesoftware.openfire.starter.ServerStarter.start(ServerStarter.java:113)
	at org.jivesoftware.openfire.starter.ServerStarter.main(ServerStarter.java:58)
2013.09.17 10:57:20 org.jivesoftware.util.JiveProperties - ConnectionManager.getConnection() failed to obtain a connection after 11 retries. The exception from the last attempt is as follows: java.sql.SQLException: The database is already in use by another process: org.hsqldb.persist.NIOLockFile@8aa1e602[file =C:\Users\Javier\workspace\Personales\openfire\target\openfire\embedded-db\openfire.lck, exists=true, locked=false, valid=false, fl =null]: java.lang.Exception:  java.io.IOException: El proceso no tiene acceso al archivo porque otro proceso tiene bloqueada una parte del archivo : C:\Users\Javier\workspace\Personales\openfire\target\openfire\embedded-db\openfire.lck
java.sql.SQLException: ConnectionManager.getConnection() failed to obtain a connection after 11 retries. The exception from the last attempt is as follows: java.sql.SQLException: The database is already in use by another process: org.hsqldb.persist.NIOLockFile@8aa1e602[file =C:\Users\Javier\workspace\Personales\openfire\target\openfire\embedded-db\openfire.lck, exists=true, locked=false, valid=false, fl =null]: java.lang.Exception:  java.io.IOException: El proceso no tiene acceso al archivo porque otro proceso tiene bloqueada una parte del archivo : C:\Users\Javier\workspace\Personales\openfire\target\openfire\embedded-db\openfire.lck
	at org.jivesoftware.database.DbConnectionManager.getConnection(DbConnectionManager.java:151)
	at org.jivesoftware.util.JiveProperties.loadProperties(JiveProperties.java:344)
	at org.jivesoftware.util.JiveProperties.init(JiveProperties.java:90)
	at org.jivesoftware.util.JiveProperties$JivePropertyHolder.<clinit>(JiveProperties.java:57)
	at org.jivesoftware.util.JiveProperties.getInstance(JiveProperties.java:69)
	at org.jivesoftware.util.JiveGlobals.getProperty(JiveGlobals.java:551)
	at org.jivesoftware.openfire.XMPPServer.initialize(XMPPServer.java:353)
	at org.jivesoftware.openfire.XMPPServer.start(XMPPServer.java:474)
	at org.jivesoftware.openfire.XMPPServer.<init>(XMPPServer.java:216)
	at sun.reflect.NativeConstructorAccessorImpl.newInstance0(Native Method)
	at sun.reflect.NativeConstructorAccessorImpl.newInstance(Unknown Source)
	at sun.reflect.DelegatingConstructorAccessorImpl.newInstance(Unknown Source)
	at java.lang.reflect.Constructor.newInstance(Unknown Source)
	at java.lang.Class.newInstance0(Unknown Source)
	at java.lang.Class.newInstance(Unknown Source)
	at org.jivesoftware.openfire.starter.ServerStarter.start(ServerStarter.java:113)
	at org.jivesoftware.openfire.starter.ServerStarter.main(ServerStarter.java:58)
2013.09.17 10:57:23 org.jivesoftware.openfire.XMPPServer - Database could not be accessed
java.sql.SQLException: ConnectionManager.getConnection() failed to obtain a connection after 11 retries. The exception from the last attempt is as follows: java.sql.SQLException: The database is already in use by another process: org.hsqldb.persist.NIOLockFile@8aa1e602[file =C:\Users\Javier\workspace\Personales\openfire\target\openfire\embedded-db\openfire.lck, exists=true, locked=false, valid=false, fl =null]: java.lang.Exception:  java.io.IOException: El proceso no tiene acceso al archivo porque otro proceso tiene bloqueada una parte del archivo : C:\Users\Javier\workspace\Personales\openfire\target\openfire\embedded-db\openfire.lck
	at org.jivesoftware.database.DbConnectionManager.getConnection(DbConnectionManager.java:151)
	at org.jivesoftware.openfire.XMPPServer.verifyDataSource(XMPPServer.java:760)
	at org.jivesoftware.openfire.XMPPServer.start(XMPPServer.java:486)
	at org.jivesoftware.openfire.XMPPServer.<init>(XMPPServer.java:216)
	at sun.reflect.NativeConstructorAccessorImpl.newInstance0(Native Method)
	at sun.reflect.NativeConstructorAccessorImpl.newInstance(Unknown Source)
	at sun.reflect.DelegatingConstructorAccessorImpl.newInstance(Unknown Source)
	at java.lang.reflect.Constructor.newInstance(Unknown Source)
	at java.lang.Class.newInstance0(Unknown Source)
	at java.lang.Class.newInstance(Unknown Source)
	at org.jivesoftware.openfire.starter.ServerStarter.start(ServerStarter.java:113)
	at org.jivesoftware.openfire.starter.ServerStarter.main(ServerStarter.java:58)
2013.09.17 10:57:23 org.jivesoftware.openfire.XMPPServer - java.sql.SQLException: ConnectionManager.getConnection() failed to obtain a connection after 11 retries. The exception from the last attempt is as follows: java.sql.SQLException: The database is already in use by another process: org.hsqldb.persist.NIOLockFile@8aa1e602[file =C:\Users\Javier\workspace\Personales\openfire\target\openfire\embedded-db\openfire.lck, exists=true, locked=false, valid=false, fl =null]: java.lang.Exception:  java.io.IOException: El proceso no tiene acceso al archivo porque otro proceso tiene bloqueada una parte del archivo : C:\Users\Javier\workspace\Personales\openfire\target\openfire\embedded-db\openfire.lck
java.lang.IllegalArgumentException: java.sql.SQLException: ConnectionManager.getConnection() failed to obtain a connection after 11 retries. The exception from the last attempt is as follows: java.sql.SQLException: The database is already in use by another process: org.hsqldb.persist.NIOLockFile@8aa1e602[file =C:\Users\Javier\workspace\Personales\openfire\target\openfire\embedded-db\openfire.lck, exists=true, locked=false, valid=false, fl =null]: java.lang.Exception:  java.io.IOException: El proceso no tiene acceso al archivo porque otro proceso tiene bloqueada una parte del archivo : C:\Users\Javier\workspace\Personales\openfire\target\openfire\embedded-db\openfire.lck
	at org.jivesoftware.openfire.XMPPServer.verifyDataSource(XMPPServer.java:770)
	at org.jivesoftware.openfire.XMPPServer.start(XMPPServer.java:486)
	at org.jivesoftware.openfire.XMPPServer.<init>(XMPPServer.java:216)
	at sun.reflect.NativeConstructorAccessorImpl.newInstance0(Native Method)
	at sun.reflect.NativeConstructorAccessorImpl.newInstance(Unknown Source)
	at sun.reflect.DelegatingConstructorAccessorImpl.newInstance(Unknown Source)
	at java.lang.reflect.Constructor.newInstance(Unknown Source)
	at java.lang.Class.newInstance0(Unknown Source)
	at java.lang.Class.newInstance(Unknown Source)
	at org.jivesoftware.openfire.starter.ServerStarter.start(ServerStarter.java:113)
	at org.jivesoftware.openfire.starter.ServerStarter.main(ServerStarter.java:58)
Caused by: java.sql.SQLException: ConnectionManager.getConnection() failed to obtain a connection after 11 retries. The exception from the last attempt is as follows: java.sql.SQLException: The database is already in use by another process: org.hsqldb.persist.NIOLockFile@8aa1e602[file =C:\Users\Javier\workspace\Personales\openfire\target\openfire\embedded-db\openfire.lck, exists=true, locked=false, valid=false, fl =null]: java.lang.Exception:  java.io.IOException: El proceso no tiene acceso al archivo porque otro proceso tiene bloqueada una parte del archivo : C:\Users\Javier\workspace\Personales\openfire\target\openfire\embedded-db\openfire.lck
	at org.jivesoftware.database.DbConnectionManager.getConnection(DbConnectionManager.java:151)
	at org.jivesoftware.openfire.XMPPServer.verifyDataSource(XMPPServer.java:760)
	... 10 more
2013.09.23 13:57:11 org.jivesoftware.util.log.util.CommonsLogFactory - Prototype
java.sql.SQLException: The database is already in use by another process: org.hsqldb.persist.NIOLockFile@8aa1e602[file =C:\Users\Javier\workspace\Personales\openfire\target\openfire\embedded-db\openfire.lck, exists=true, locked=false, valid=false, fl =null]: java.lang.Exception: checkHeartbeat(): lock file [C:\Users\Javier\workspace\Personales\openfire\target\openfire\embedded-db\openfire.lck] is presumably locked by another process.
	at org.hsqldb.jdbc.Util.sqlException(Unknown Source)
	at org.hsqldb.jdbc.jdbcConnection.<init>(Unknown Source)
	at org.hsqldb.jdbcDriver.getConnection(Unknown Source)
	at org.hsqldb.jdbcDriver.connect(Unknown Source)
	at java.sql.DriverManager.getConnection(Unknown Source)
	at java.sql.DriverManager.getConnection(Unknown Source)
	at org.logicalcobwebs.proxool.DefaultConnectionBuilder.buildConnection(DefaultConnectionBuilder.java:39)
	at org.logicalcobwebs.proxool.Prototyper.buildConnection(Prototyper.java:159)
	at org.logicalcobwebs.proxool.Prototyper.sweep(Prototyper.java:102)
	at org.logicalcobwebs.proxool.PrototyperThread.run(PrototyperThread.java:44)
2013.09.23 13:57:11 org.jivesoftware.database.DbConnectionManager - The database is already in use by another process: org.hsqldb.persist.NIOLockFile@8aa1e602[file =C:\Users\Javier\workspace\Personales\openfire\target\openfire\embedded-db\openfire.lck, exists=true, locked=false, valid=false, fl =null]: java.lang.Exception: checkHeartbeat(): lock file [C:\Users\Javier\workspace\Personales\openfire\target\openfire\embedded-db\openfire.lck] is presumably locked by another process.
java.sql.SQLException: The database is already in use by another process: org.hsqldb.persist.NIOLockFile@8aa1e602[file =C:\Users\Javier\workspace\Personales\openfire\target\openfire\embedded-db\openfire.lck, exists=true, locked=false, valid=false, fl =null]: java.lang.Exception: checkHeartbeat(): lock file [C:\Users\Javier\workspace\Personales\openfire\target\openfire\embedded-db\openfire.lck] is presumably locked by another process.
	at org.hsqldb.jdbc.Util.sqlException(Unknown Source)
	at org.hsqldb.jdbc.jdbcConnection.<init>(Unknown Source)
	at org.hsqldb.jdbcDriver.getConnection(Unknown Source)
	at org.hsqldb.jdbcDriver.connect(Unknown Source)
	at java.sql.DriverManager.getConnection(Unknown Source)
	at java.sql.DriverManager.getConnection(Unknown Source)
	at org.logicalcobwebs.proxool.DefaultConnectionBuilder.buildConnection(DefaultConnectionBuilder.java:39)
	at org.logicalcobwebs.proxool.Prototyper.buildConnection(Prototyper.java:159)
	at org.logicalcobwebs.proxool.ConnectionPool.getConnection(ConnectionPool.java:211)
	at org.logicalcobwebs.proxool.ProxoolDriver.connect(ProxoolDriver.java:89)
	at java.sql.DriverManager.getConnection(Unknown Source)
	at java.sql.DriverManager.getConnection(Unknown Source)
	at org.jivesoftware.database.EmbeddedConnectionProvider.getConnection(EmbeddedConnectionProvider.java:61)
	at org.jivesoftware.database.DbConnectionManager.setConnectionProvider(DbConnectionManager.java:620)
	at org.jivesoftware.database.DbConnectionManager.getConnection(DbConnectionManager.java:100)
	at org.jivesoftware.util.JiveProperties.loadProperties(JiveProperties.java:344)
	at org.jivesoftware.util.JiveProperties.init(JiveProperties.java:90)
	at org.jivesoftware.util.JiveProperties$JivePropertyHolder.<clinit>(JiveProperties.java:57)
	at org.jivesoftware.util.JiveProperties.getInstance(JiveProperties.java:69)
	at org.jivesoftware.util.JiveGlobals.getProperty(JiveGlobals.java:551)
	at org.jivesoftware.openfire.XMPPServer.initialize(XMPPServer.java:353)
	at org.jivesoftware.openfire.XMPPServer.start(XMPPServer.java:474)
	at org.jivesoftware.openfire.XMPPServer.<init>(XMPPServer.java:216)
	at sun.reflect.NativeConstructorAccessorImpl.newInstance0(Native Method)
	at sun.reflect.NativeConstructorAccessorImpl.newInstance(Unknown Source)
	at sun.reflect.DelegatingConstructorAccessorImpl.newInstance(Unknown Source)
	at java.lang.reflect.Constructor.newInstance(Unknown Source)
	at java.lang.Class.newInstance0(Unknown Source)
	at java.lang.Class.newInstance(Unknown Source)
	at org.jivesoftware.openfire.starter.ServerStarter.start(ServerStarter.java:113)
	at org.jivesoftware.openfire.starter.ServerStarter.main(ServerStarter.java:58)
2013.09.23 13:57:14 org.jivesoftware.util.JiveProperties - ConnectionManager.getConnection() failed to obtain a connection after 11 retries. The exception from the last attempt is as follows: java.sql.SQLException: The database is already in use by another process: org.hsqldb.persist.NIOLockFile@8aa1e602[file =C:\Users\Javier\workspace\Personales\openfire\target\openfire\embedded-db\openfire.lck, exists=true, locked=false, valid=false, fl =null]: java.lang.Exception: checkHeartbeat(): lock file [C:\Users\Javier\workspace\Personales\openfire\target\openfire\embedded-db\openfire.lck] is presumably locked by another process.
java.sql.SQLException: ConnectionManager.getConnection() failed to obtain a connection after 11 retries. The exception from the last attempt is as follows: java.sql.SQLException: The database is already in use by another process: org.hsqldb.persist.NIOLockFile@8aa1e602[file =C:\Users\Javier\workspace\Personales\openfire\target\openfire\embedded-db\openfire.lck, exists=true, locked=false, valid=false, fl =null]: java.lang.Exception: checkHeartbeat(): lock file [C:\Users\Javier\workspace\Personales\openfire\target\openfire\embedded-db\openfire.lck] is presumably locked by another process.
	at org.jivesoftware.database.DbConnectionManager.getConnection(DbConnectionManager.java:151)
	at org.jivesoftware.util.JiveProperties.loadProperties(JiveProperties.java:344)
	at org.jivesoftware.util.JiveProperties.init(JiveProperties.java:90)
	at org.jivesoftware.util.JiveProperties$JivePropertyHolder.<clinit>(JiveProperties.java:57)
	at org.jivesoftware.util.JiveProperties.getInstance(JiveProperties.java:69)
	at org.jivesoftware.util.JiveGlobals.getProperty(JiveGlobals.java:551)
	at org.jivesoftware.openfire.XMPPServer.initialize(XMPPServer.java:353)
	at org.jivesoftware.openfire.XMPPServer.start(XMPPServer.java:474)
	at org.jivesoftware.openfire.XMPPServer.<init>(XMPPServer.java:216)
	at sun.reflect.NativeConstructorAccessorImpl.newInstance0(Native Method)
	at sun.reflect.NativeConstructorAccessorImpl.newInstance(Unknown Source)
	at sun.reflect.DelegatingConstructorAccessorImpl.newInstance(Unknown Source)
	at java.lang.reflect.Constructor.newInstance(Unknown Source)
	at java.lang.Class.newInstance0(Unknown Source)
	at java.lang.Class.newInstance(Unknown Source)
	at org.jivesoftware.openfire.starter.ServerStarter.start(ServerStarter.java:113)
	at org.jivesoftware.openfire.starter.ServerStarter.main(ServerStarter.java:58)
2013.09.23 13:57:17 org.jivesoftware.util.JiveProperties - Unique constraint violation: SYS_IDX_59 in statement [INSERT INTO ofProperty(name, propValue) VALUES(?,?)]
java.sql.SQLException: Unique constraint violation: SYS_IDX_59 in statement [INSERT INTO ofProperty(name, propValue) VALUES(?,?)]
	at org.hsqldb.jdbc.Util.throwError(Unknown Source)
	at org.hsqldb.jdbc.jdbcPreparedStatement.executeUpdate(Unknown Source)
	at sun.reflect.NativeMethodAccessorImpl.invoke0(Native Method)
	at sun.reflect.NativeMethodAccessorImpl.invoke(Unknown Source)
	at sun.reflect.DelegatingMethodAccessorImpl.invoke(Unknown Source)
	at java.lang.reflect.Method.invoke(Unknown Source)
	at org.logicalcobwebs.proxool.ProxyStatement.invoke(ProxyStatement.java:100)
	at org.logicalcobwebs.proxool.ProxyStatement.intercept(ProxyStatement.java:57)
	at $java.lang.AutoCloseable$$EnhancerByProxool$$dca9d71e.executeUpdate(<generated>)
	at org.jivesoftware.util.JiveProperties.insertProperty(JiveProperties.java:294)
	at org.jivesoftware.util.JiveProperties.put(JiveProperties.java:236)
	at org.jivesoftware.util.JiveGlobals.setProperty(JiveGlobals.java:718)
	at org.jivesoftware.openfire.SessionManager.initialize(SessionManager.java:1283)
	at org.jivesoftware.openfire.XMPPServer.initModules(XMPPServer.java:602)
	at org.jivesoftware.openfire.XMPPServer.start(XMPPServer.java:491)
	at org.jivesoftware.openfire.XMPPServer.<init>(XMPPServer.java:216)
	at sun.reflect.NativeConstructorAccessorImpl.newInstance0(Native Method)
	at sun.reflect.NativeConstructorAccessorImpl.newInstance(Unknown Source)
	at sun.reflect.DelegatingConstructorAccessorImpl.newInstance(Unknown Source)
	at java.lang.reflect.Constructor.newInstance(Unknown Source)
	at java.lang.Class.newInstance0(Unknown Source)
	at java.lang.Class.newInstance(Unknown Source)
	at org.jivesoftware.openfire.starter.ServerStarter.start(ServerStarter.java:113)
	at org.jivesoftware.openfire.starter.ServerStarter.main(ServerStarter.java:58)
2013.09.23 13:57:22 org.jivesoftware.util.JiveProperties - Unique constraint violation: SYS_IDX_59 in statement [INSERT INTO ofProperty(name, propValue) VALUES(?,?)]
java.sql.SQLException: Unique constraint violation: SYS_IDX_59 in statement [INSERT INTO ofProperty(name, propValue) VALUES(?,?)]
	at org.hsqldb.jdbc.Util.throwError(Unknown Source)
	at org.hsqldb.jdbc.jdbcPreparedStatement.executeUpdate(Unknown Source)
	at sun.reflect.NativeMethodAccessorImpl.invoke0(Native Method)
	at sun.reflect.NativeMethodAccessorImpl.invoke(Unknown Source)
	at sun.reflect.DelegatingMethodAccessorImpl.invoke(Unknown Source)
	at java.lang.reflect.Method.invoke(Unknown Source)
	at org.logicalcobwebs.proxool.ProxyStatement.invoke(ProxyStatement.java:100)
	at org.logicalcobwebs.proxool.ProxyStatement.intercept(ProxyStatement.java:57)
	at $java.lang.AutoCloseable$$EnhancerByProxool$$dca9d71e.executeUpdate(<generated>)
	at org.jivesoftware.util.JiveProperties.insertProperty(JiveProperties.java:294)
	at org.jivesoftware.util.JiveProperties.put(JiveProperties.java:236)
	at org.jivesoftware.util.JiveGlobals.setProperty(JiveGlobals.java:718)
	at org.jivesoftware.openfire.net.SASLAuthentication.setSharedSecretAllowed(SASLAuthentication.java:400)
	at org.jivesoftware.xmpp.workgroup.WorkgroupManager.start(WorkgroupManager.java:217)
	at org.jivesoftware.openfire.component.InternalComponentManager.addComponent(InternalComponentManager.java:158)
	at org.jivesoftware.openfire.fastpath.FastpathPlugin.workgroupManagerStart(FastpathPlugin.java:100)
	at org.jivesoftware.openfire.fastpath.FastpathPlugin.initializePlugin(FastpathPlugin.java:80)
	at org.jivesoftware.openfire.container.PluginManager.loadPlugin(PluginManager.java:483)
	at org.jivesoftware.openfire.container.PluginManager.access$1(PluginManager.java:282)
	at org.jivesoftware.openfire.container.PluginManager$PluginMonitor.run(PluginManager.java:1073)
	at java.util.concurrent.Executors$RunnableAdapter.call(Unknown Source)
	at java.util.concurrent.FutureTask$Sync.innerRunAndReset(Unknown Source)
	at java.util.concurrent.FutureTask.runAndReset(Unknown Source)
	at java.util.concurrent.ScheduledThreadPoolExecutor$ScheduledFutureTask.access$301(Unknown Source)
	at java.util.concurrent.ScheduledThreadPoolExecutor$ScheduledFutureTask.run(Unknown Source)
	at java.util.concurrent.ThreadPoolExecutor.runWorker(Unknown Source)
	at java.util.concurrent.ThreadPoolExecutor$Worker.run(Unknown Source)
	at java.lang.Thread.run(Unknown Source)
2013.09.23 13:57:22 org.jivesoftware.xmpp.workgroup.WorkgroupManager - Username demo already exists
org.jivesoftware.openfire.user.UserAlreadyExistsException: Username demo already exists
	at org.jivesoftware.openfire.user.DefaultUserProvider.createUser(DefaultUserProvider.java:128)
	at org.jivesoftware.openfire.user.UserManager.createUser(UserManager.java:178)
	at org.jivesoftware.xmpp.workgroup.WorkgroupManager.createDemoUser(WorkgroupManager.java:940)
	at org.jivesoftware.xmpp.workgroup.WorkgroupManager.start(WorkgroupManager.java:224)
	at org.jivesoftware.openfire.component.InternalComponentManager.addComponent(InternalComponentManager.java:158)
	at org.jivesoftware.openfire.fastpath.FastpathPlugin.workgroupManagerStart(FastpathPlugin.java:100)
	at org.jivesoftware.openfire.fastpath.FastpathPlugin.initializePlugin(FastpathPlugin.java:80)
	at org.jivesoftware.openfire.container.PluginManager.loadPlugin(PluginManager.java:483)
	at org.jivesoftware.openfire.container.PluginManager.access$1(PluginManager.java:282)
	at org.jivesoftware.openfire.container.PluginManager$PluginMonitor.run(PluginManager.java:1073)
	at java.util.concurrent.Executors$RunnableAdapter.call(Unknown Source)
	at java.util.concurrent.FutureTask$Sync.innerRunAndReset(Unknown Source)
	at java.util.concurrent.FutureTask.runAndReset(Unknown Source)
	at java.util.concurrent.ScheduledThreadPoolExecutor$ScheduledFutureTask.access$301(Unknown Source)
	at java.util.concurrent.ScheduledThreadPoolExecutor$ScheduledFutureTask.run(Unknown Source)
	at java.util.concurrent.ThreadPoolExecutor.runWorker(Unknown Source)
	at java.util.concurrent.ThreadPoolExecutor$Worker.run(Unknown Source)
	at java.lang.Thread.run(Unknown Source)
2013.09.23 13:57:22 org.jivesoftware.util.JiveProperties - Unique constraint violation: SYS_IDX_59 in statement [INSERT INTO ofProperty(name, propValue) VALUES(?,?)]
java.sql.SQLException: Unique constraint violation: SYS_IDX_59 in statement [INSERT INTO ofProperty(name, propValue) VALUES(?,?)]
	at org.hsqldb.jdbc.Util.throwError(Unknown Source)
	at org.hsqldb.jdbc.jdbcPreparedStatement.executeUpdate(Unknown Source)
	at sun.reflect.NativeMethodAccessorImpl.invoke0(Native Method)
	at sun.reflect.NativeMethodAccessorImpl.invoke(Unknown Source)
	at sun.reflect.DelegatingMethodAccessorImpl.invoke(Unknown Source)
	at java.lang.reflect.Method.invoke(Unknown Source)
	at org.logicalcobwebs.proxool.ProxyStatement.invoke(ProxyStatement.java:100)
	at org.logicalcobwebs.proxool.ProxyStatement.intercept(ProxyStatement.java:57)
	at $java.lang.AutoCloseable$$EnhancerByProxool$$dca9d71e.executeUpdate(<generated>)
	at org.jivesoftware.util.JiveProperties.insertProperty(JiveProperties.java:294)
	at org.jivesoftware.util.JiveProperties.put(JiveProperties.java:236)
	at org.jivesoftware.util.JiveGlobals.setProperty(JiveGlobals.java:718)
	at org.jivesoftware.xmpp.workgroup.WorkgroupManager.start(WorkgroupManager.java:228)
	at org.jivesoftware.openfire.component.InternalComponentManager.addComponent(InternalComponentManager.java:158)
	at org.jivesoftware.openfire.fastpath.FastpathPlugin.workgroupManagerStart(FastpathPlugin.java:100)
	at org.jivesoftware.openfire.fastpath.FastpathPlugin.initializePlugin(FastpathPlugin.java:80)
	at org.jivesoftware.openfire.container.PluginManager.loadPlugin(PluginManager.java:483)
	at org.jivesoftware.openfire.container.PluginManager.access$1(PluginManager.java:282)
	at org.jivesoftware.openfire.container.PluginManager$PluginMonitor.run(PluginManager.java:1073)
	at java.util.concurrent.Executors$RunnableAdapter.call(Unknown Source)
	at java.util.concurrent.FutureTask$Sync.innerRunAndReset(Unknown Source)
	at java.util.concurrent.FutureTask.runAndReset(Unknown Source)
	at java.util.concurrent.ScheduledThreadPoolExecutor$ScheduledFutureTask.access$301(Unknown Source)
	at java.util.concurrent.ScheduledThreadPoolExecutor$ScheduledFutureTask.run(Unknown Source)
	at java.util.concurrent.ThreadPoolExecutor.runWorker(Unknown Source)
	at java.util.concurrent.ThreadPoolExecutor$Worker.run(Unknown Source)
	at java.lang.Thread.run(Unknown Source)
2013.09.23 13:57:24 org.jivesoftware.util.JiveProperties - Unique constraint violation: SYS_IDX_59 in statement [INSERT INTO ofProperty(name, propValue) VALUES(?,?)]
java.sql.SQLException: Unique constraint violation: SYS_IDX_59 in statement [INSERT INTO ofProperty(name, propValue) VALUES(?,?)]
	at org.hsqldb.jdbc.Util.throwError(Unknown Source)
	at org.hsqldb.jdbc.jdbcPreparedStatement.executeUpdate(Unknown Source)
	at sun.reflect.NativeMethodAccessorImpl.invoke0(Native Method)
	at sun.reflect.NativeMethodAccessorImpl.invoke(Unknown Source)
	at sun.reflect.DelegatingMethodAccessorImpl.invoke(Unknown Source)
	at java.lang.reflect.Method.invoke(Unknown Source)
	at org.logicalcobwebs.proxool.ProxyStatement.invoke(ProxyStatement.java:100)
	at org.logicalcobwebs.proxool.ProxyStatement.intercept(ProxyStatement.java:57)
	at $java.lang.AutoCloseable$$EnhancerByProxool$$dca9d71e.executeUpdate(<generated>)
	at org.jivesoftware.util.JiveProperties.insertProperty(JiveProperties.java:294)
	at org.jivesoftware.util.JiveProperties.put(JiveProperties.java:236)
	at org.jivesoftware.util.JiveGlobals.setProperty(JiveGlobals.java:718)
	at org.jivesoftware.util.cache.CacheFactory.setCacheTypeProperty(CacheFactory.java:269)
	at org.jivesoftware.openfire.container.PluginCacheRegistry.registerCache(PluginCacheRegistry.java:71)
	at org.jivesoftware.openfire.container.PluginCacheConfigurator.registerCache(PluginCacheConfigurator.java:98)
	at org.jivesoftware.openfire.container.PluginCacheConfigurator.configure(PluginCacheConfigurator.java:80)
	at org.jivesoftware.openfire.container.PluginManager.configureCaches(PluginManager.java:552)
	at org.jivesoftware.openfire.container.PluginManager.loadPlugin(PluginManager.java:478)
	at org.jivesoftware.openfire.container.PluginManager.access$1(PluginManager.java:282)
	at org.jivesoftware.openfire.container.PluginManager$PluginMonitor.run(PluginManager.java:1073)
	at java.util.concurrent.Executors$RunnableAdapter.call(Unknown Source)
	at java.util.concurrent.FutureTask$Sync.innerRunAndReset(Unknown Source)
	at java.util.concurrent.FutureTask.runAndReset(Unknown Source)
	at java.util.concurrent.ScheduledThreadPoolExecutor$ScheduledFutureTask.access$301(Unknown Source)
	at java.util.concurrent.ScheduledThreadPoolExecutor$ScheduledFutureTask.run(Unknown Source)
	at java.util.concurrent.ThreadPoolExecutor.runWorker(Unknown Source)
	at java.util.concurrent.ThreadPoolExecutor$Worker.run(Unknown Source)
	at java.lang.Thread.run(Unknown Source)
2013.09.23 13:57:24 org.jivesoftware.util.JiveProperties - Unique constraint violation: SYS_IDX_59 in statement [INSERT INTO ofProperty(name, propValue) VALUES(?,?)]
java.sql.SQLException: Unique constraint violation: SYS_IDX_59 in statement [INSERT INTO ofProperty(name, propValue) VALUES(?,?)]
	at org.hsqldb.jdbc.Util.throwError(Unknown Source)
	at org.hsqldb.jdbc.jdbcPreparedStatement.executeUpdate(Unknown Source)
	at sun.reflect.NativeMethodAccessorImpl.invoke0(Native Method)
	at sun.reflect.NativeMethodAccessorImpl.invoke(Unknown Source)
	at sun.reflect.DelegatingMethodAccessorImpl.invoke(Unknown Source)
	at java.lang.reflect.Method.invoke(Unknown Source)
	at org.logicalcobwebs.proxool.ProxyStatement.invoke(ProxyStatement.java:100)
	at org.logicalcobwebs.proxool.ProxyStatement.intercept(ProxyStatement.java:57)
	at $java.lang.AutoCloseable$$EnhancerByProxool$$dca9d71e.executeUpdate(<generated>)
	at org.jivesoftware.util.JiveProperties.insertProperty(JiveProperties.java:294)
	at org.jivesoftware.util.JiveProperties.put(JiveProperties.java:236)
	at org.jivesoftware.util.JiveGlobals.setProperty(JiveGlobals.java:718)
	at org.jivesoftware.util.cache.CacheFactory.setMaxSizeProperty(CacheFactory.java:234)
	at org.jivesoftware.openfire.container.PluginCacheRegistry.registerCache(PluginCacheRegistry.java:72)
	at org.jivesoftware.openfire.container.PluginCacheConfigurator.registerCache(PluginCacheConfigurator.java:98)
	at org.jivesoftware.openfire.container.PluginCacheConfigurator.configure(PluginCacheConfigurator.java:80)
	at org.jivesoftware.openfire.container.PluginManager.configureCaches(PluginManager.java:552)
	at org.jivesoftware.openfire.container.PluginManager.loadPlugin(PluginManager.java:478)
	at org.jivesoftware.openfire.container.PluginManager.access$1(PluginManager.java:282)
	at org.jivesoftware.openfire.container.PluginManager$PluginMonitor.run(PluginManager.java:1073)
	at java.util.concurrent.Executors$RunnableAdapter.call(Unknown Source)
	at java.util.concurrent.FutureTask$Sync.innerRunAndReset(Unknown Source)
	at java.util.concurrent.FutureTask.runAndReset(Unknown Source)
	at java.util.concurrent.ScheduledThreadPoolExecutor$ScheduledFutureTask.access$301(Unknown Source)
	at java.util.concurrent.ScheduledThreadPoolExecutor$ScheduledFutureTask.run(Unknown Source)
	at java.util.concurrent.ThreadPoolExecutor.runWorker(Unknown Source)
	at java.util.concurrent.ThreadPoolExecutor$Worker.run(Unknown Source)
	at java.lang.Thread.run(Unknown Source)
2013.09.23 13:57:24 org.jivesoftware.util.JiveProperties - Unique constraint violation: SYS_IDX_59 in statement [INSERT INTO ofProperty(name, propValue) VALUES(?,?)]
java.sql.SQLException: Unique constraint violation: SYS_IDX_59 in statement [INSERT INTO ofProperty(name, propValue) VALUES(?,?)]
	at org.hsqldb.jdbc.Util.throwError(Unknown Source)
	at org.hsqldb.jdbc.jdbcPreparedStatement.executeUpdate(Unknown Source)
	at sun.reflect.NativeMethodAccessorImpl.invoke0(Native Method)
	at sun.reflect.NativeMethodAccessorImpl.invoke(Unknown Source)
	at sun.reflect.DelegatingMethodAccessorImpl.invoke(Unknown Source)
	at java.lang.reflect.Method.invoke(Unknown Source)
	at org.logicalcobwebs.proxool.ProxyStatement.invoke(ProxyStatement.java:100)
	at org.logicalcobwebs.proxool.ProxyStatement.intercept(ProxyStatement.java:57)
	at $java.lang.AutoCloseable$$EnhancerByProxool$$dca9d71e.executeUpdate(<generated>)
	at org.jivesoftware.util.JiveProperties.insertProperty(JiveProperties.java:294)
	at org.jivesoftware.util.JiveProperties.put(JiveProperties.java:236)
	at org.jivesoftware.util.JiveGlobals.setProperty(JiveGlobals.java:718)
	at org.jivesoftware.util.cache.CacheFactory.setMaxLifetimeProperty(CacheFactory.java:260)
	at org.jivesoftware.openfire.container.PluginCacheRegistry.registerCache(PluginCacheRegistry.java:73)
	at org.jivesoftware.openfire.container.PluginCacheConfigurator.registerCache(PluginCacheConfigurator.java:98)
	at org.jivesoftware.openfire.container.PluginCacheConfigurator.configure(PluginCacheConfigurator.java:80)
	at org.jivesoftware.openfire.container.PluginManager.configureCaches(PluginManager.java:552)
	at org.jivesoftware.openfire.container.PluginManager.loadPlugin(PluginManager.java:478)
	at org.jivesoftware.openfire.container.PluginManager.access$1(PluginManager.java:282)
	at org.jivesoftware.openfire.container.PluginManager$PluginMonitor.run(PluginManager.java:1073)
	at java.util.concurrent.Executors$RunnableAdapter.call(Unknown Source)
	at java.util.concurrent.FutureTask$Sync.innerRunAndReset(Unknown Source)
	at java.util.concurrent.FutureTask.runAndReset(Unknown Source)
	at java.util.concurrent.ScheduledThreadPoolExecutor$ScheduledFutureTask.access$301(Unknown Source)
	at java.util.concurrent.ScheduledThreadPoolExecutor$ScheduledFutureTask.run(Unknown Source)
	at java.util.concurrent.ThreadPoolExecutor.runWorker(Unknown Source)
	at java.util.concurrent.ThreadPoolExecutor$Worker.run(Unknown Source)
	at java.lang.Thread.run(Unknown Source)
2013.09.23 13:57:24 org.jivesoftware.util.JiveProperties - Unique constraint violation: SYS_IDX_59 in statement [INSERT INTO ofProperty(name, propValue) VALUES(?,?)]
java.sql.SQLException: Unique constraint violation: SYS_IDX_59 in statement [INSERT INTO ofProperty(name, propValue) VALUES(?,?)]
	at org.hsqldb.jdbc.Util.throwError(Unknown Source)
	at org.hsqldb.jdbc.jdbcPreparedStatement.executeUpdate(Unknown Source)
	at sun.reflect.NativeMethodAccessorImpl.invoke0(Native Method)
	at sun.reflect.NativeMethodAccessorImpl.invoke(Unknown Source)
	at sun.reflect.DelegatingMethodAccessorImpl.invoke(Unknown Source)
	at java.lang.reflect.Method.invoke(Unknown Source)
	at org.logicalcobwebs.proxool.ProxyStatement.invoke(ProxyStatement.java:100)
	at org.logicalcobwebs.proxool.ProxyStatement.intercept(ProxyStatement.java:57)
	at $java.lang.AutoCloseable$$EnhancerByProxool$$dca9d71e.executeUpdate(<generated>)
	at org.jivesoftware.util.JiveProperties.insertProperty(JiveProperties.java:294)
	at org.jivesoftware.util.JiveProperties.put(JiveProperties.java:236)
	at org.jivesoftware.util.JiveGlobals.setProperty(JiveGlobals.java:718)
	at org.jivesoftware.util.cache.CacheFactory.setMinCacheSize(CacheFactory.java:279)
	at org.jivesoftware.openfire.container.PluginCacheRegistry.registerCache(PluginCacheRegistry.java:74)
	at org.jivesoftware.openfire.container.PluginCacheConfigurator.registerCache(PluginCacheConfigurator.java:98)
	at org.jivesoftware.openfire.container.PluginCacheConfigurator.configure(PluginCacheConfigurator.java:80)
	at org.jivesoftware.openfire.container.PluginManager.configureCaches(PluginManager.java:552)
	at org.jivesoftware.openfire.container.PluginManager.loadPlugin(PluginManager.java:478)
	at org.jivesoftware.openfire.container.PluginManager.access$1(PluginManager.java:282)
	at org.jivesoftware.openfire.container.PluginManager$PluginMonitor.run(PluginManager.java:1073)
	at java.util.concurrent.Executors$RunnableAdapter.call(Unknown Source)
	at java.util.concurrent.FutureTask$Sync.innerRunAndReset(Unknown Source)
	at java.util.concurrent.FutureTask.runAndReset(Unknown Source)
	at java.util.concurrent.ScheduledThreadPoolExecutor$ScheduledFutureTask.access$301(Unknown Source)
	at java.util.concurrent.ScheduledThreadPoolExecutor$ScheduledFutureTask.run(Unknown Source)
	at java.util.concurrent.ThreadPoolExecutor.runWorker(Unknown Source)
	at java.util.concurrent.ThreadPoolExecutor$Worker.run(Unknown Source)
	at java.lang.Thread.run(Unknown Source)
2013.09.23 13:57:24 org.jivesoftware.util.JiveProperties - Unique constraint violation: SYS_IDX_59 in statement [INSERT INTO ofProperty(name, propValue) VALUES(?,?)]
java.sql.SQLException: Unique constraint violation: SYS_IDX_59 in statement [INSERT INTO ofProperty(name, propValue) VALUES(?,?)]
	at org.hsqldb.jdbc.Util.throwError(Unknown Source)
	at org.hsqldb.jdbc.jdbcPreparedStatement.executeUpdate(Unknown Source)
	at sun.reflect.NativeMethodAccessorImpl.invoke0(Native Method)
	at sun.reflect.NativeMethodAccessorImpl.invoke(Unknown Source)
	at sun.reflect.DelegatingMethodAccessorImpl.invoke(Unknown Source)
	at java.lang.reflect.Method.invoke(Unknown Source)
	at org.logicalcobwebs.proxool.ProxyStatement.invoke(ProxyStatement.java:100)
	at org.logicalcobwebs.proxool.ProxyStatement.intercept(ProxyStatement.java:57)
	at $java.lang.AutoCloseable$$EnhancerByProxool$$dca9d71e.executeUpdate(<generated>)
	at org.jivesoftware.util.JiveProperties.insertProperty(JiveProperties.java:294)
	at org.jivesoftware.util.JiveProperties.put(JiveProperties.java:236)
	at org.jivesoftware.util.JiveGlobals.setProperty(JiveGlobals.java:718)
	at org.jivesoftware.util.cache.CacheFactory.setCacheTypeProperty(CacheFactory.java:269)
	at org.jivesoftware.openfire.container.PluginCacheRegistry.registerCache(PluginCacheRegistry.java:71)
	at org.jivesoftware.openfire.container.PluginCacheConfigurator.registerCache(PluginCacheConfigurator.java:98)
	at org.jivesoftware.openfire.container.PluginCacheConfigurator.configure(PluginCacheConfigurator.java:80)
	at org.jivesoftware.openfire.container.PluginManager.configureCaches(PluginManager.java:552)
	at org.jivesoftware.openfire.container.PluginManager.loadPlugin(PluginManager.java:478)
	at org.jivesoftware.openfire.container.PluginManager.access$1(PluginManager.java:282)
	at org.jivesoftware.openfire.container.PluginManager$PluginMonitor.run(PluginManager.java:1073)
	at java.util.concurrent.Executors$RunnableAdapter.call(Unknown Source)
	at java.util.concurrent.FutureTask$Sync.innerRunAndReset(Unknown Source)
	at java.util.concurrent.FutureTask.runAndReset(Unknown Source)
	at java.util.concurrent.ScheduledThreadPoolExecutor$ScheduledFutureTask.access$301(Unknown Source)
	at java.util.concurrent.ScheduledThreadPoolExecutor$ScheduledFutureTask.run(Unknown Source)
	at java.util.concurrent.ThreadPoolExecutor.runWorker(Unknown Source)
	at java.util.concurrent.ThreadPoolExecutor$Worker.run(Unknown Source)
	at java.lang.Thread.run(Unknown Source)
2013.09.23 13:57:24 org.jivesoftware.util.JiveProperties - Unique constraint violation: SYS_IDX_59 in statement [INSERT INTO ofProperty(name, propValue) VALUES(?,?)]
java.sql.SQLException: Unique constraint violation: SYS_IDX_59 in statement [INSERT INTO ofProperty(name, propValue) VALUES(?,?)]
	at org.hsqldb.jdbc.Util.throwError(Unknown Source)
	at org.hsqldb.jdbc.jdbcPreparedStatement.executeUpdate(Unknown Source)
	at sun.reflect.NativeMethodAccessorImpl.invoke0(Native Method)
	at sun.reflect.NativeMethodAccessorImpl.invoke(Unknown Source)
	at sun.reflect.DelegatingMethodAccessorImpl.invoke(Unknown Source)
	at java.lang.reflect.Method.invoke(Unknown Source)
	at org.logicalcobwebs.proxool.ProxyStatement.invoke(ProxyStatement.java:100)
	at org.logicalcobwebs.proxool.ProxyStatement.intercept(ProxyStatement.java:57)
	at $java.lang.AutoCloseable$$EnhancerByProxool$$dca9d71e.executeUpdate(<generated>)
	at org.jivesoftware.util.JiveProperties.insertProperty(JiveProperties.java:294)
	at org.jivesoftware.util.JiveProperties.put(JiveProperties.java:236)
	at org.jivesoftware.util.JiveGlobals.setProperty(JiveGlobals.java:718)
	at org.jivesoftware.util.cache.CacheFactory.setMaxSizeProperty(CacheFactory.java:234)
	at org.jivesoftware.openfire.container.PluginCacheRegistry.registerCache(PluginCacheRegistry.java:72)
	at org.jivesoftware.openfire.container.PluginCacheConfigurator.registerCache(PluginCacheConfigurator.java:98)
	at org.jivesoftware.openfire.container.PluginCacheConfigurator.configure(PluginCacheConfigurator.java:80)
	at org.jivesoftware.openfire.container.PluginManager.configureCaches(PluginManager.java:552)
	at org.jivesoftware.openfire.container.PluginManager.loadPlugin(PluginManager.java:478)
	at org.jivesoftware.openfire.container.PluginManager.access$1(PluginManager.java:282)
	at org.jivesoftware.openfire.container.PluginManager$PluginMonitor.run(PluginManager.java:1073)
	at java.util.concurrent.Executors$RunnableAdapter.call(Unknown Source)
	at java.util.concurrent.FutureTask$Sync.innerRunAndReset(Unknown Source)
	at java.util.concurrent.FutureTask.runAndReset(Unknown Source)
	at java.util.concurrent.ScheduledThreadPoolExecutor$ScheduledFutureTask.access$301(Unknown Source)
	at java.util.concurrent.ScheduledThreadPoolExecutor$ScheduledFutureTask.run(Unknown Source)
	at java.util.concurrent.ThreadPoolExecutor.runWorker(Unknown Source)
	at java.util.concurrent.ThreadPoolExecutor$Worker.run(Unknown Source)
	at java.lang.Thread.run(Unknown Source)
2013.09.23 13:57:24 org.jivesoftware.util.JiveProperties - Unique constraint violation: SYS_IDX_59 in statement [INSERT INTO ofProperty(name, propValue) VALUES(?,?)]
java.sql.SQLException: Unique constraint violation: SYS_IDX_59 in statement [INSERT INTO ofProperty(name, propValue) VALUES(?,?)]
	at org.hsqldb.jdbc.Util.throwError(Unknown Source)
	at org.hsqldb.jdbc.jdbcPreparedStatement.executeUpdate(Unknown Source)
	at sun.reflect.NativeMethodAccessorImpl.invoke0(Native Method)
	at sun.reflect.NativeMethodAccessorImpl.invoke(Unknown Source)
	at sun.reflect.DelegatingMethodAccessorImpl.invoke(Unknown Source)
	at java.lang.reflect.Method.invoke(Unknown Source)
	at org.logicalcobwebs.proxool.ProxyStatement.invoke(ProxyStatement.java:100)
	at org.logicalcobwebs.proxool.ProxyStatement.intercept(ProxyStatement.java:57)
	at $java.lang.AutoCloseable$$EnhancerByProxool$$dca9d71e.executeUpdate(<generated>)
	at org.jivesoftware.util.JiveProperties.insertProperty(JiveProperties.java:294)
	at org.jivesoftware.util.JiveProperties.put(JiveProperties.java:236)
	at org.jivesoftware.util.JiveGlobals.setProperty(JiveGlobals.java:718)
	at org.jivesoftware.util.cache.CacheFactory.setMaxLifetimeProperty(CacheFactory.java:260)
	at org.jivesoftware.openfire.container.PluginCacheRegistry.registerCache(PluginCacheRegistry.java:73)
	at org.jivesoftware.openfire.container.PluginCacheConfigurator.registerCache(PluginCacheConfigurator.java:98)
	at org.jivesoftware.openfire.container.PluginCacheConfigurator.configure(PluginCacheConfigurator.java:80)
	at org.jivesoftware.openfire.container.PluginManager.configureCaches(PluginManager.java:552)
	at org.jivesoftware.openfire.container.PluginManager.loadPlugin(PluginManager.java:478)
	at org.jivesoftware.openfire.container.PluginManager.access$1(PluginManager.java:282)
	at org.jivesoftware.openfire.container.PluginManager$PluginMonitor.run(PluginManager.java:1073)
	at java.util.concurrent.Executors$RunnableAdapter.call(Unknown Source)
	at java.util.concurrent.FutureTask$Sync.innerRunAndReset(Unknown Source)
	at java.util.concurrent.FutureTask.runAndReset(Unknown Source)
	at java.util.concurrent.ScheduledThreadPoolExecutor$ScheduledFutureTask.access$301(Unknown Source)
	at java.util.concurrent.ScheduledThreadPoolExecutor$ScheduledFutureTask.run(Unknown Source)
	at java.util.concurrent.ThreadPoolExecutor.runWorker(Unknown Source)
	at java.util.concurrent.ThreadPoolExecutor$Worker.run(Unknown Source)
	at java.lang.Thread.run(Unknown Source)
2013.09.23 13:57:24 org.jivesoftware.util.JiveProperties - Unique constraint violation: SYS_IDX_59 in statement [INSERT INTO ofProperty(name, propValue) VALUES(?,?)]
java.sql.SQLException: Unique constraint violation: SYS_IDX_59 in statement [INSERT INTO ofProperty(name, propValue) VALUES(?,?)]
	at org.hsqldb.jdbc.Util.throwError(Unknown Source)
	at org.hsqldb.jdbc.jdbcPreparedStatement.executeUpdate(Unknown Source)
	at sun.reflect.NativeMethodAccessorImpl.invoke0(Native Method)
	at sun.reflect.NativeMethodAccessorImpl.invoke(Unknown Source)
	at sun.reflect.DelegatingMethodAccessorImpl.invoke(Unknown Source)
	at java.lang.reflect.Method.invoke(Unknown Source)
	at org.logicalcobwebs.proxool.ProxyStatement.invoke(ProxyStatement.java:100)
	at org.logicalcobwebs.proxool.ProxyStatement.intercept(ProxyStatement.java:57)
	at $java.lang.AutoCloseable$$EnhancerByProxool$$dca9d71e.executeUpdate(<generated>)
	at org.jivesoftware.util.JiveProperties.insertProperty(JiveProperties.java:294)
	at org.jivesoftware.util.JiveProperties.put(JiveProperties.java:236)
	at org.jivesoftware.util.JiveGlobals.setProperty(JiveGlobals.java:718)
	at org.jivesoftware.util.cache.CacheFactory.setMinCacheSize(CacheFactory.java:279)
	at org.jivesoftware.openfire.container.PluginCacheRegistry.registerCache(PluginCacheRegistry.java:74)
	at org.jivesoftware.openfire.container.PluginCacheConfigurator.registerCache(PluginCacheConfigurator.java:98)
	at org.jivesoftware.openfire.container.PluginCacheConfigurator.configure(PluginCacheConfigurator.java:80)
	at org.jivesoftware.openfire.container.PluginManager.configureCaches(PluginManager.java:552)
	at org.jivesoftware.openfire.container.PluginManager.loadPlugin(PluginManager.java:478)
	at org.jivesoftware.openfire.container.PluginManager.access$1(PluginManager.java:282)
	at org.jivesoftware.openfire.container.PluginManager$PluginMonitor.run(PluginManager.java:1073)
	at java.util.concurrent.Executors$RunnableAdapter.call(Unknown Source)
	at java.util.concurrent.FutureTask$Sync.innerRunAndReset(Unknown Source)
	at java.util.concurrent.FutureTask.runAndReset(Unknown Source)
	at java.util.concurrent.ScheduledThreadPoolExecutor$ScheduledFutureTask.access$301(Unknown Source)
	at java.util.concurrent.ScheduledThreadPoolExecutor$ScheduledFutureTask.run(Unknown Source)
	at java.util.concurrent.ThreadPoolExecutor.runWorker(Unknown Source)
	at java.util.concurrent.ThreadPoolExecutor$Worker.run(Unknown Source)
	at java.lang.Thread.run(Unknown Source)
2013.09.23 13:57:25 org.jivesoftware.util.JiveProperties - Unique constraint violation: SYS_IDX_59 in statement [INSERT INTO ofProperty(name, propValue) VALUES(?,?)]
java.sql.SQLException: Unique constraint violation: SYS_IDX_59 in statement [INSERT INTO ofProperty(name, propValue) VALUES(?,?)]
	at org.hsqldb.jdbc.Util.throwError(Unknown Source)
	at org.hsqldb.jdbc.jdbcPreparedStatement.executeUpdate(Unknown Source)
	at sun.reflect.NativeMethodAccessorImpl.invoke0(Native Method)
	at sun.reflect.NativeMethodAccessorImpl.invoke(Unknown Source)
	at sun.reflect.DelegatingMethodAccessorImpl.invoke(Unknown Source)
	at java.lang.reflect.Method.invoke(Unknown Source)
	at org.logicalcobwebs.proxool.ProxyStatement.invoke(ProxyStatement.java:100)
	at org.logicalcobwebs.proxool.ProxyStatement.intercept(ProxyStatement.java:57)
	at $java.lang.AutoCloseable$$EnhancerByProxool$$dca9d71e.executeUpdate(<generated>)
	at org.jivesoftware.util.JiveProperties.insertProperty(JiveProperties.java:294)
	at org.jivesoftware.util.JiveProperties.put(JiveProperties.java:236)
	at org.jivesoftware.util.JiveGlobals.setProperty(JiveGlobals.java:718)
	at org.jivesoftware.openfire.plugin.UserServicePlugin.setSecret(UserServicePlugin.java:320)
	at org.jivesoftware.openfire.plugin.UserServicePlugin.initializePlugin(UserServicePlugin.java:74)
	at org.jivesoftware.openfire.container.PluginManager.loadPlugin(PluginManager.java:483)
	at org.jivesoftware.openfire.container.PluginManager.access$1(PluginManager.java:282)
	at org.jivesoftware.openfire.container.PluginManager$PluginMonitor.run(PluginManager.java:1073)
	at java.util.concurrent.Executors$RunnableAdapter.call(Unknown Source)
	at java.util.concurrent.FutureTask$Sync.innerRunAndReset(Unknown Source)
	at java.util.concurrent.FutureTask.runAndReset(Unknown Source)
	at java.util.concurrent.ScheduledThreadPoolExecutor$ScheduledFutureTask.access$301(Unknown Source)
	at java.util.concurrent.ScheduledThreadPoolExecutor$ScheduledFutureTask.run(Unknown Source)
	at java.util.concurrent.ThreadPoolExecutor.runWorker(Unknown Source)
	at java.util.concurrent.ThreadPoolExecutor$Worker.run(Unknown Source)
	at java.lang.Thread.run(Unknown Source)
2013.09.23 13:57:54 org.jivesoftware.util.JiveProperties - Unique constraint violation: SYS_IDX_59 in statement [INSERT INTO ofProperty(name, propValue) VALUES(?,?)]
java.sql.SQLException: Unique constraint violation: SYS_IDX_59 in statement [INSERT INTO ofProperty(name, propValue) VALUES(?,?)]
	at org.hsqldb.jdbc.Util.throwError(Unknown Source)
	at org.hsqldb.jdbc.jdbcPreparedStatement.executeUpdate(Unknown Source)
	at sun.reflect.NativeMethodAccessorImpl.invoke0(Native Method)
	at sun.reflect.NativeMethodAccessorImpl.invoke(Unknown Source)
	at sun.reflect.DelegatingMethodAccessorImpl.invoke(Unknown Source)
	at java.lang.reflect.Method.invoke(Unknown Source)
	at org.logicalcobwebs.proxool.ProxyStatement.invoke(ProxyStatement.java:100)
	at org.logicalcobwebs.proxool.ProxyStatement.intercept(ProxyStatement.java:57)
	at $java.lang.AutoCloseable$$EnhancerByProxool$$dca9d71e.executeUpdate(<generated>)
	at org.jivesoftware.util.JiveProperties.insertProperty(JiveProperties.java:294)
	at org.jivesoftware.util.JiveProperties.put(JiveProperties.java:236)
	at org.jivesoftware.util.JiveGlobals.setProperty(JiveGlobals.java:718)
	at org.jivesoftware.openfire.update.UpdateManager$1.run(UpdateManager.java:151)
2013.09.23 13:57:58 org.jivesoftware.util.JiveProperties - Unique constraint violation: SYS_IDX_59 in statement [INSERT INTO ofProperty(name, propValue) VALUES(?,?)]
java.sql.SQLException: Unique constraint violation: SYS_IDX_59 in statement [INSERT INTO ofProperty(name, propValue) VALUES(?,?)]
	at org.hsqldb.jdbc.Util.throwError(Unknown Source)
	at org.hsqldb.jdbc.jdbcPreparedStatement.executeUpdate(Unknown Source)
	at sun.reflect.NativeMethodAccessorImpl.invoke0(Native Method)
	at sun.reflect.NativeMethodAccessorImpl.invoke(Unknown Source)
	at sun.reflect.DelegatingMethodAccessorImpl.invoke(Unknown Source)
	at java.lang.reflect.Method.invoke(Unknown Source)
	at org.logicalcobwebs.proxool.ProxyStatement.invoke(ProxyStatement.java:100)
	at org.logicalcobwebs.proxool.ProxyStatement.intercept(ProxyStatement.java:57)
	at $java.lang.AutoCloseable$$EnhancerByProxool$$dca9d71e.executeUpdate(<generated>)
	at org.jivesoftware.util.JiveProperties.insertProperty(JiveProperties.java:294)
	at org.jivesoftware.util.JiveProperties.put(JiveProperties.java:236)
	at org.jivesoftware.util.JiveGlobals.setProperty(JiveGlobals.java:718)
	at org.jivesoftware.openfire.auth.AuthFactory.getCipher(AuthFactory.java:280)
	at org.jivesoftware.openfire.auth.AuthFactory.decryptPassword(AuthFactory.java:253)
	at org.jivesoftware.openfire.auth.DefaultAuthProvider.getPassword(DefaultAuthProvider.java:156)
	at org.jivesoftware.openfire.auth.AuthFactory.getPassword(AuthFactory.java:156)
	at org.jivesoftware.openfire.net.XMPPCallbackHandler.handle(XMPPCallbackHandler.java:86)
	at com.sun.security.sasl.digest.DigestMD5Server.validateClientResponse(Unknown Source)
	at com.sun.security.sasl.digest.DigestMD5Server.evaluateResponse(Unknown Source)
	at org.jivesoftware.openfire.net.SASLAuthentication.handle(SASLAuthentication.java:325)
	at org.jivesoftware.openfire.net.StanzaHandler.process(StanzaHandler.java:183)
	at org.jivesoftware.openfire.nio.ConnectionHandler.messageReceived(ConnectionHandler.java:183)
	at org.apache.mina.common.support.AbstractIoFilterChain$TailFilter.messageReceived(AbstractIoFilterChain.java:570)
	at org.apache.mina.common.support.AbstractIoFilterChain.callNextMessageReceived(AbstractIoFilterChain.java:299)
	at org.apache.mina.common.support.AbstractIoFilterChain.access$1100(AbstractIoFilterChain.java:53)
	at org.apache.mina.common.support.AbstractIoFilterChain$EntryImpl$1.messageReceived(AbstractIoFilterChain.java:648)
	at org.apache.mina.common.IoFilterAdapter.messageReceived(IoFilterAdapter.java:80)
	at org.apache.mina.common.support.AbstractIoFilterChain.callNextMessageReceived(AbstractIoFilterChain.java:299)
	at org.apache.mina.common.support.AbstractIoFilterChain.access$1100(AbstractIoFilterChain.java:53)
	at org.apache.mina.common.support.AbstractIoFilterChain$EntryImpl$1.messageReceived(AbstractIoFilterChain.java:648)
	at org.apache.mina.filter.codec.support.SimpleProtocolDecoderOutput.flush(SimpleProtocolDecoderOutput.java:58)
	at org.apache.mina.filter.codec.ProtocolCodecFilter.messageReceived(ProtocolCodecFilter.java:185)
	at org.apache.mina.common.support.AbstractIoFilterChain.callNextMessageReceived(AbstractIoFilterChain.java:299)
	at org.apache.mina.common.support.AbstractIoFilterChain.access$1100(AbstractIoFilterChain.java:53)
	at org.apache.mina.common.support.AbstractIoFilterChain$EntryImpl$1.messageReceived(AbstractIoFilterChain.java:648)
	at org.apache.mina.common.IoFilterAdapter.messageReceived(IoFilterAdapter.java:80)
	at org.jivesoftware.openfire.plugin.RawPrintFilter.messageReceived(RawPrintFilter.java:66)
	at org.apache.mina.common.support.AbstractIoFilterChain.callNextMessageReceived(AbstractIoFilterChain.java:299)
	at org.apache.mina.common.support.AbstractIoFilterChain.access$1100(AbstractIoFilterChain.java:53)
	at org.apache.mina.common.support.AbstractIoFilterChain$EntryImpl$1.messageReceived(AbstractIoFilterChain.java:648)
	at org.apache.mina.common.IoFilterAdapter.messageReceived(IoFilterAdapter.java:80)
	at cl.clayster.exi.EXIFilter.messageReceived(EXIFilter.java:54)
	at org.apache.mina.common.support.AbstractIoFilterChain.callNextMessageReceived(AbstractIoFilterChain.java:299)
	at org.apache.mina.common.support.AbstractIoFilterChain.access$1100(AbstractIoFilterChain.java:53)
	at org.apache.mina.common.support.AbstractIoFilterChain$EntryImpl$1.messageReceived(AbstractIoFilterChain.java:648)
	at org.apache.mina.filter.executor.ExecutorFilter.processEvent(ExecutorFilter.java:239)
	at org.apache.mina.filter.executor.ExecutorFilter$ProcessEventsRunnable.run(ExecutorFilter.java:283)
	at java.util.concurrent.ThreadPoolExecutor.runWorker(Unknown Source)
	at java.util.concurrent.ThreadPoolExecutor$Worker.run(Unknown Source)
	at org.apache.mina.util.NamePreservingRunnable.run(NamePreservingRunnable.java:51)
	at java.lang.Thread.run(Unknown Source)
2013.09.23 13:58:15 org.jivesoftware.database.DbConnectionManager - The database is already in use by another process: org.hsqldb.persist.NIOLockFile@8aa1e602[file =C:\Users\Javier\workspace\Personales\openfire\target\openfire\embedded-db\openfire.lck, exists=true, locked=false, valid=false, fl =null]: java.lang.Exception: checkHeartbeat(): lock file [C:\Users\Javier\workspace\Personales\openfire\target\openfire\embedded-db\openfire.lck] is presumably locked by another process.
java.sql.SQLException: The database is already in use by another process: org.hsqldb.persist.NIOLockFile@8aa1e602[file =C:\Users\Javier\workspace\Personales\openfire\target\openfire\embedded-db\openfire.lck, exists=true, locked=false, valid=false, fl =null]: java.lang.Exception: checkHeartbeat(): lock file [C:\Users\Javier\workspace\Personales\openfire\target\openfire\embedded-db\openfire.lck] is presumably locked by another process.
	at org.hsqldb.jdbc.Util.sqlException(Unknown Source)
	at org.hsqldb.jdbc.jdbcConnection.<init>(Unknown Source)
	at org.hsqldb.jdbcDriver.getConnection(Unknown Source)
	at org.hsqldb.jdbcDriver.connect(Unknown Source)
	at java.sql.DriverManager.getConnection(Unknown Source)
	at java.sql.DriverManager.getConnection(Unknown Source)
	at org.logicalcobwebs.proxool.DefaultConnectionBuilder.buildConnection(DefaultConnectionBuilder.java:39)
	at org.logicalcobwebs.proxool.Prototyper.buildConnection(Prototyper.java:159)
	at org.logicalcobwebs.proxool.ConnectionPool.getConnection(ConnectionPool.java:211)
	at org.logicalcobwebs.proxool.ProxoolDriver.connect(ProxoolDriver.java:89)
	at java.sql.DriverManager.getConnection(Unknown Source)
	at java.sql.DriverManager.getConnection(Unknown Source)
	at org.jivesoftware.database.EmbeddedConnectionProvider.getConnection(EmbeddedConnectionProvider.java:61)
	at org.jivesoftware.database.DbConnectionManager.setConnectionProvider(DbConnectionManager.java:620)
	at org.jivesoftware.database.DbConnectionManager.getConnection(DbConnectionManager.java:100)
	at org.jivesoftware.util.JiveProperties.loadProperties(JiveProperties.java:344)
	at org.jivesoftware.util.JiveProperties.init(JiveProperties.java:90)
	at org.jivesoftware.util.JiveProperties$JivePropertyHolder.<clinit>(JiveProperties.java:57)
	at org.jivesoftware.util.JiveProperties.getInstance(JiveProperties.java:69)
	at org.jivesoftware.util.JiveGlobals.getProperty(JiveGlobals.java:551)
	at org.jivesoftware.openfire.XMPPServer.initialize(XMPPServer.java:353)
	at org.jivesoftware.openfire.XMPPServer.start(XMPPServer.java:474)
	at org.jivesoftware.openfire.XMPPServer.<init>(XMPPServer.java:216)
	at sun.reflect.NativeConstructorAccessorImpl.newInstance0(Native Method)
	at sun.reflect.NativeConstructorAccessorImpl.newInstance(Unknown Source)
	at sun.reflect.DelegatingConstructorAccessorImpl.newInstance(Unknown Source)
	at java.lang.reflect.Constructor.newInstance(Unknown Source)
	at java.lang.Class.newInstance0(Unknown Source)
	at java.lang.Class.newInstance(Unknown Source)
	at org.jivesoftware.openfire.starter.ServerStarter.start(ServerStarter.java:113)
	at org.jivesoftware.openfire.starter.ServerStarter.main(ServerStarter.java:58)
2013.09.23 14:13:07 org.jivesoftware.database.DbConnectionManager - The database is already in use by another process: org.hsqldb.persist.NIOLockFile@8aa1e602[file =C:\Users\Javier\workspace\Personales\openfire\target\openfire\embedded-db\openfire.lck, exists=true, locked=false, valid=false, fl =null]: java.lang.Exception: checkHeartbeat(): lock file [C:\Users\Javier\workspace\Personales\openfire\target\openfire\embedded-db\openfire.lck] is presumably locked by another process.
java.sql.SQLException: The database is already in use by another process: org.hsqldb.persist.NIOLockFile@8aa1e602[file =C:\Users\Javier\workspace\Personales\openfire\target\openfire\embedded-db\openfire.lck, exists=true, locked=false, valid=false, fl =null]: java.lang.Exception: checkHeartbeat(): lock file [C:\Users\Javier\workspace\Personales\openfire\target\openfire\embedded-db\openfire.lck] is presumably locked by another process.
	at org.hsqldb.jdbc.Util.sqlException(Unknown Source)
	at org.hsqldb.jdbc.jdbcConnection.<init>(Unknown Source)
	at org.hsqldb.jdbcDriver.getConnection(Unknown Source)
	at org.hsqldb.jdbcDriver.connect(Unknown Source)
	at java.sql.DriverManager.getConnection(Unknown Source)
	at java.sql.DriverManager.getConnection(Unknown Source)
	at org.logicalcobwebs.proxool.DefaultConnectionBuilder.buildConnection(DefaultConnectionBuilder.java:39)
	at org.logicalcobwebs.proxool.Prototyper.buildConnection(Prototyper.java:159)
	at org.logicalcobwebs.proxool.ConnectionPool.getConnection(ConnectionPool.java:211)
	at org.logicalcobwebs.proxool.ProxoolDriver.connect(ProxoolDriver.java:89)
	at java.sql.DriverManager.getConnection(Unknown Source)
	at java.sql.DriverManager.getConnection(Unknown Source)
	at org.jivesoftware.database.EmbeddedConnectionProvider.getConnection(EmbeddedConnectionProvider.java:61)
	at org.jivesoftware.database.DbConnectionManager.setConnectionProvider(DbConnectionManager.java:620)
	at org.jivesoftware.database.DbConnectionManager.getConnection(DbConnectionManager.java:100)
	at org.jivesoftware.util.JiveProperties.loadProperties(JiveProperties.java:344)
	at org.jivesoftware.util.JiveProperties.init(JiveProperties.java:90)
	at org.jivesoftware.util.JiveProperties$JivePropertyHolder.<clinit>(JiveProperties.java:57)
	at org.jivesoftware.util.JiveProperties.getInstance(JiveProperties.java:69)
	at org.jivesoftware.util.JiveGlobals.getProperty(JiveGlobals.java:551)
	at org.jivesoftware.openfire.XMPPServer.initialize(XMPPServer.java:353)
	at org.jivesoftware.openfire.XMPPServer.start(XMPPServer.java:474)
	at org.jivesoftware.openfire.XMPPServer.<init>(XMPPServer.java:216)
	at sun.reflect.NativeConstructorAccessorImpl.newInstance0(Native Method)
	at sun.reflect.NativeConstructorAccessorImpl.newInstance(Unknown Source)
	at sun.reflect.DelegatingConstructorAccessorImpl.newInstance(Unknown Source)
	at java.lang.reflect.Constructor.newInstance(Unknown Source)
	at java.lang.Class.newInstance0(Unknown Source)
	at java.lang.Class.newInstance(Unknown Source)
	at org.jivesoftware.openfire.starter.ServerStarter.start(ServerStarter.java:113)
	at org.jivesoftware.openfire.starter.ServerStarter.main(ServerStarter.java:58)
2013.09.23 14:13:07 org.jivesoftware.util.log.util.CommonsLogFactory - Prototype
java.sql.SQLException: The database is already in use by another process: org.hsqldb.persist.NIOLockFile@8aa1e602[file =C:\Users\Javier\workspace\Personales\openfire\target\openfire\embedded-db\openfire.lck, exists=true, locked=false, valid=false, fl =null]: java.lang.Exception: checkHeartbeat(): lock file [C:\Users\Javier\workspace\Personales\openfire\target\openfire\embedded-db\openfire.lck] is presumably locked by another process.
	at org.hsqldb.jdbc.Util.sqlException(Unknown Source)
	at org.hsqldb.jdbc.jdbcConnection.<init>(Unknown Source)
	at org.hsqldb.jdbcDriver.getConnection(Unknown Source)
	at org.hsqldb.jdbcDriver.connect(Unknown Source)
	at java.sql.DriverManager.getConnection(Unknown Source)
	at java.sql.DriverManager.getConnection(Unknown Source)
	at org.logicalcobwebs.proxool.DefaultConnectionBuilder.buildConnection(DefaultConnectionBuilder.java:39)
	at org.logicalcobwebs.proxool.Prototyper.buildConnection(Prototyper.java:159)
	at org.logicalcobwebs.proxool.Prototyper.sweep(Prototyper.java:102)
	at org.logicalcobwebs.proxool.PrototyperThread.run(PrototyperThread.java:44)
2013.09.23 15:16:16 org.jivesoftware.util.log.util.CommonsLogFactory - Prototype
java.sql.SQLException: The database is already in use by another process: org.hsqldb.persist.NIOLockFile@8aa1e602[file =C:\Users\Javier\workspace\Personales\openfire\target\openfire\embedded-db\openfire.lck, exists=true, locked=false, valid=false, fl =null]: java.lang.Exception:  java.io.IOException: El proceso no tiene acceso al archivo porque otro proceso tiene bloqueada una parte del archivo : C:\Users\Javier\workspace\Personales\openfire\target\openfire\embedded-db\openfire.lck
	at org.hsqldb.jdbc.Util.sqlException(Unknown Source)
	at org.hsqldb.jdbc.jdbcConnection.<init>(Unknown Source)
	at org.hsqldb.jdbcDriver.getConnection(Unknown Source)
	at org.hsqldb.jdbcDriver.connect(Unknown Source)
	at java.sql.DriverManager.getConnection(Unknown Source)
	at java.sql.DriverManager.getConnection(Unknown Source)
	at org.logicalcobwebs.proxool.DefaultConnectionBuilder.buildConnection(DefaultConnectionBuilder.java:39)
	at org.logicalcobwebs.proxool.Prototyper.buildConnection(Prototyper.java:159)
	at org.logicalcobwebs.proxool.Prototyper.sweep(Prototyper.java:102)
	at org.logicalcobwebs.proxool.PrototyperThread.run(PrototyperThread.java:44)
2013.09.23 15:16:16 org.jivesoftware.database.DbConnectionManager - The database is already in use by another process: org.hsqldb.persist.NIOLockFile@8aa1e602[file =C:\Users\Javier\workspace\Personales\openfire\target\openfire\embedded-db\openfire.lck, exists=true, locked=false, valid=false, fl =null]: java.lang.Exception:  java.io.IOException: El proceso no tiene acceso al archivo porque otro proceso tiene bloqueada una parte del archivo : C:\Users\Javier\workspace\Personales\openfire\target\openfire\embedded-db\openfire.lck
java.sql.SQLException: The database is already in use by another process: org.hsqldb.persist.NIOLockFile@8aa1e602[file =C:\Users\Javier\workspace\Personales\openfire\target\openfire\embedded-db\openfire.lck, exists=true, locked=false, valid=false, fl =null]: java.lang.Exception:  java.io.IOException: El proceso no tiene acceso al archivo porque otro proceso tiene bloqueada una parte del archivo : C:\Users\Javier\workspace\Personales\openfire\target\openfire\embedded-db\openfire.lck
	at org.hsqldb.jdbc.Util.sqlException(Unknown Source)
	at org.hsqldb.jdbc.jdbcConnection.<init>(Unknown Source)
	at org.hsqldb.jdbcDriver.getConnection(Unknown Source)
	at org.hsqldb.jdbcDriver.connect(Unknown Source)
	at java.sql.DriverManager.getConnection(Unknown Source)
	at java.sql.DriverManager.getConnection(Unknown Source)
	at org.logicalcobwebs.proxool.DefaultConnectionBuilder.buildConnection(DefaultConnectionBuilder.java:39)
	at org.logicalcobwebs.proxool.Prototyper.buildConnection(Prototyper.java:159)
	at org.logicalcobwebs.proxool.ConnectionPool.getConnection(ConnectionPool.java:211)
	at org.logicalcobwebs.proxool.ProxoolDriver.connect(ProxoolDriver.java:89)
	at java.sql.DriverManager.getConnection(Unknown Source)
	at java.sql.DriverManager.getConnection(Unknown Source)
	at org.jivesoftware.database.EmbeddedConnectionProvider.getConnection(EmbeddedConnectionProvider.java:61)
	at org.jivesoftware.database.DbConnectionManager.setConnectionProvider(DbConnectionManager.java:620)
	at org.jivesoftware.database.DbConnectionManager.getConnection(DbConnectionManager.java:100)
	at org.jivesoftware.util.JiveProperties.loadProperties(JiveProperties.java:344)
	at org.jivesoftware.util.JiveProperties.init(JiveProperties.java:90)
	at org.jivesoftware.util.JiveProperties$JivePropertyHolder.<clinit>(JiveProperties.java:57)
	at org.jivesoftware.util.JiveProperties.getInstance(JiveProperties.java:69)
	at org.jivesoftware.util.JiveGlobals.getProperty(JiveGlobals.java:551)
	at org.jivesoftware.openfire.XMPPServer.initialize(XMPPServer.java:353)
	at org.jivesoftware.openfire.XMPPServer.start(XMPPServer.java:474)
	at org.jivesoftware.openfire.XMPPServer.<init>(XMPPServer.java:216)
	at sun.reflect.NativeConstructorAccessorImpl.newInstance0(Native Method)
	at sun.reflect.NativeConstructorAccessorImpl.newInstance(Unknown Source)
	at sun.reflect.DelegatingConstructorAccessorImpl.newInstance(Unknown Source)
	at java.lang.reflect.Constructor.newInstance(Unknown Source)
	at java.lang.Class.newInstance0(Unknown Source)
	at java.lang.Class.newInstance(Unknown Source)
	at org.jivesoftware.openfire.starter.ServerStarter.start(ServerStarter.java:113)
	at org.jivesoftware.openfire.starter.ServerStarter.main(ServerStarter.java:58)
2013.09.23 15:16:19 org.jivesoftware.util.JiveProperties - ConnectionManager.getConnection() failed to obtain a connection after 11 retries. The exception from the last attempt is as follows: java.sql.SQLException: The database is already in use by another process: org.hsqldb.persist.NIOLockFile@8aa1e602[file =C:\Users\Javier\workspace\Personales\openfire\target\openfire\embedded-db\openfire.lck, exists=true, locked=false, valid=false, fl =null]: java.lang.Exception:  java.io.IOException: El proceso no tiene acceso al archivo porque otro proceso tiene bloqueada una parte del archivo : C:\Users\Javier\workspace\Personales\openfire\target\openfire\embedded-db\openfire.lck
java.sql.SQLException: ConnectionManager.getConnection() failed to obtain a connection after 11 retries. The exception from the last attempt is as follows: java.sql.SQLException: The database is already in use by another process: org.hsqldb.persist.NIOLockFile@8aa1e602[file =C:\Users\Javier\workspace\Personales\openfire\target\openfire\embedded-db\openfire.lck, exists=true, locked=false, valid=false, fl =null]: java.lang.Exception:  java.io.IOException: El proceso no tiene acceso al archivo porque otro proceso tiene bloqueada una parte del archivo : C:\Users\Javier\workspace\Personales\openfire\target\openfire\embedded-db\openfire.lck
	at org.jivesoftware.database.DbConnectionManager.getConnection(DbConnectionManager.java:151)
	at org.jivesoftware.util.JiveProperties.loadProperties(JiveProperties.java:344)
	at org.jivesoftware.util.JiveProperties.init(JiveProperties.java:90)
	at org.jivesoftware.util.JiveProperties$JivePropertyHolder.<clinit>(JiveProperties.java:57)
	at org.jivesoftware.util.JiveProperties.getInstance(JiveProperties.java:69)
	at org.jivesoftware.util.JiveGlobals.getProperty(JiveGlobals.java:551)
	at org.jivesoftware.openfire.XMPPServer.initialize(XMPPServer.java:353)
	at org.jivesoftware.openfire.XMPPServer.start(XMPPServer.java:474)
	at org.jivesoftware.openfire.XMPPServer.<init>(XMPPServer.java:216)
	at sun.reflect.NativeConstructorAccessorImpl.newInstance0(Native Method)
	at sun.reflect.NativeConstructorAccessorImpl.newInstance(Unknown Source)
	at sun.reflect.DelegatingConstructorAccessorImpl.newInstance(Unknown Source)
	at java.lang.reflect.Constructor.newInstance(Unknown Source)
	at java.lang.Class.newInstance0(Unknown Source)
	at java.lang.Class.newInstance(Unknown Source)
	at org.jivesoftware.openfire.starter.ServerStarter.start(ServerStarter.java:113)
	at org.jivesoftware.openfire.starter.ServerStarter.main(ServerStarter.java:58)
2013.09.23 15:16:22 org.jivesoftware.openfire.XMPPServer - Database could not be accessed
java.sql.SQLException: ConnectionManager.getConnection() failed to obtain a connection after 11 retries. The exception from the last attempt is as follows: java.sql.SQLException: The database is already in use by another process: org.hsqldb.persist.NIOLockFile@8aa1e602[file =C:\Users\Javier\workspace\Personales\openfire\target\openfire\embedded-db\openfire.lck, exists=true, locked=false, valid=false, fl =null]: java.lang.Exception:  java.io.IOException: El proceso no tiene acceso al archivo porque otro proceso tiene bloqueada una parte del archivo : C:\Users\Javier\workspace\Personales\openfire\target\openfire\embedded-db\openfire.lck
	at org.jivesoftware.database.DbConnectionManager.getConnection(DbConnectionManager.java:151)
	at org.jivesoftware.openfire.XMPPServer.verifyDataSource(XMPPServer.java:760)
	at org.jivesoftware.openfire.XMPPServer.start(XMPPServer.java:486)
	at org.jivesoftware.openfire.XMPPServer.<init>(XMPPServer.java:216)
	at sun.reflect.NativeConstructorAccessorImpl.newInstance0(Native Method)
	at sun.reflect.NativeConstructorAccessorImpl.newInstance(Unknown Source)
	at sun.reflect.DelegatingConstructorAccessorImpl.newInstance(Unknown Source)
	at java.lang.reflect.Constructor.newInstance(Unknown Source)
	at java.lang.Class.newInstance0(Unknown Source)
	at java.lang.Class.newInstance(Unknown Source)
	at org.jivesoftware.openfire.starter.ServerStarter.start(ServerStarter.java:113)
	at org.jivesoftware.openfire.starter.ServerStarter.main(ServerStarter.java:58)
2013.09.23 15:16:22 org.jivesoftware.openfire.XMPPServer - java.sql.SQLException: ConnectionManager.getConnection() failed to obtain a connection after 11 retries. The exception from the last attempt is as follows: java.sql.SQLException: The database is already in use by another process: org.hsqldb.persist.NIOLockFile@8aa1e602[file =C:\Users\Javier\workspace\Personales\openfire\target\openfire\embedded-db\openfire.lck, exists=true, locked=false, valid=false, fl =null]: java.lang.Exception:  java.io.IOException: El proceso no tiene acceso al archivo porque otro proceso tiene bloqueada una parte del archivo : C:\Users\Javier\workspace\Personales\openfire\target\openfire\embedded-db\openfire.lck
java.lang.IllegalArgumentException: java.sql.SQLException: ConnectionManager.getConnection() failed to obtain a connection after 11 retries. The exception from the last attempt is as follows: java.sql.SQLException: The database is already in use by another process: org.hsqldb.persist.NIOLockFile@8aa1e602[file =C:\Users\Javier\workspace\Personales\openfire\target\openfire\embedded-db\openfire.lck, exists=true, locked=false, valid=false, fl =null]: java.lang.Exception:  java.io.IOException: El proceso no tiene acceso al archivo porque otro proceso tiene bloqueada una parte del archivo : C:\Users\Javier\workspace\Personales\openfire\target\openfire\embedded-db\openfire.lck
	at org.jivesoftware.openfire.XMPPServer.verifyDataSource(XMPPServer.java:770)
	at org.jivesoftware.openfire.XMPPServer.start(XMPPServer.java:486)
	at org.jivesoftware.openfire.XMPPServer.<init>(XMPPServer.java:216)
	at sun.reflect.NativeConstructorAccessorImpl.newInstance0(Native Method)
	at sun.reflect.NativeConstructorAccessorImpl.newInstance(Unknown Source)
	at sun.reflect.DelegatingConstructorAccessorImpl.newInstance(Unknown Source)
	at java.lang.reflect.Constructor.newInstance(Unknown Source)
	at java.lang.Class.newInstance0(Unknown Source)
	at java.lang.Class.newInstance(Unknown Source)
	at org.jivesoftware.openfire.starter.ServerStarter.start(ServerStarter.java:113)
	at org.jivesoftware.openfire.starter.ServerStarter.main(ServerStarter.java:58)
Caused by: java.sql.SQLException: ConnectionManager.getConnection() failed to obtain a connection after 11 retries. The exception from the last attempt is as follows: java.sql.SQLException: The database is already in use by another process: org.hsqldb.persist.NIOLockFile@8aa1e602[file =C:\Users\Javier\workspace\Personales\openfire\target\openfire\embedded-db\openfire.lck, exists=true, locked=false, valid=false, fl =null]: java.lang.Exception:  java.io.IOException: El proceso no tiene acceso al archivo porque otro proceso tiene bloqueada una parte del archivo : C:\Users\Javier\workspace\Personales\openfire\target\openfire\embedded-db\openfire.lck
	at org.jivesoftware.database.DbConnectionManager.getConnection(DbConnectionManager.java:151)
	at org.jivesoftware.openfire.XMPPServer.verifyDataSource(XMPPServer.java:760)
	... 10 more
